Workbook

Sheet січень
A1: ОСББ "Карбишева - 22" | N1: 37465042 | W1: 4.1
B2: Відомість нарахувань та оплати мешканців за утримання будинку
B3: у січні 2026 року
A6: № кв. | B6: ПІБ | C6: Особ. рах. | D6: Д-Т | E6: К-Т | F6: Пільга % | G6: Заг.площа | H6: Пільг. Площа | I6: Тариф | J6: 100% нарах. | K6: Пільгова сума | L6: сплачені суми пільг за реєстрами | M6: Коригування | N6: До сплати | O6: Сплачено | P6: Д-Т | Q6: К-Т
A7: 1 | B7: Бережний В.М. | C7: 1001 | D7: 823.15 | E7: 0 | F7: 0 | G7: 64.26 | H7: 0 | I7: =W$1 -> 4.1 | J7: =ROUND(G7*I7,2) -> 263.47 | N7: =ROUND((G7*I7)-K7-L7-M7,2) -> 263.47 | P7: =ROUND(IF(D7=0,IF((N7-E7-O7)>0,(N7-E7-O7),0),IF((D7+N7-O7)>0,(D7+N7-O7),0)),2) -> 1086.62 | Q7: =ROUND(IF(E7=0,IF((D7+N7-O7)<0,ABS(D7+N7-O7),0),IF((N7-E7-O7)<0,ABS(N7-E7-O7),0)),2) -> 0
A8: 2 | B8: Старикова Т.О. | C8: 1002 | D8: 199.71 | E8: 0 | F8: 0 | G8: 48.71 | H8: 0 | I8: =W$1 -> 4.1 | J8: =ROUND(G8*I8,2) -> 199.71 | N8: =ROUND((G8*I8)-K8-L8-M8,2) -> 199.71 | O8: 199.71 | P8: =ROUND(IF(D8=0,IF((N8-E8-O8)>0,(N8-E8-O8),0),IF((D8+N8-O8)>0,(D8+N8-O8),0)),2) -> 199.71 | Q8: =ROUND(IF(E8=0,IF((D8+N8-O8)<0,ABS(D8+N8-O8),0),IF((N8-E8-O8)<0,ABS(N8-E8-O8),0)),2) -> 0
A9: 3 | B9: Мазур Т.В. | C9: 1003 | D9: 143.5 | E9: 0 | F9: 0 | G9: 35 | H9: 0 | I9: =W$1 -> 4.1 | J9: =ROUND(G9*I9,2) -> 143.5 | N9: =ROUND((G9*I9)-K9-L9-M9,2) -> 143.5 | P9: =ROUND(IF(D9=0,IF((N9-E9-O9)>0,(N9-E9-O9),0),IF((D9+N9-O9)>0,(D9+N9-O9),0)),2) -> 287 | Q9: =ROUND(IF(E9=0,IF((D9+N9-O9)<0,ABS(D9+N9-O9),0),IF((N9-E9-O9)<0,ABS(N9-E9-O9),0)),2) -> 0
A10: 4 | B10: Сокол О.В. | C10: 1004 | D10: 0 | E10: 252.56 | F10: 0 | G10: 61.6 | H10: 0 | I10: =W$1 -> 4.1 | J10: =ROUND(G10*I10,2) -> 252.56 | N10: =ROUND((G10*I10)-K10-L10-M10,2) -> 252.56 | P10: =ROUND(IF(D10=0,IF((N10-E10-O10)>0,(N10-E10-O10),0),IF((D10+N10-O10)>0,(D10+N10-O10),0)),2) -> 0 | Q10: =ROUND(IF(E10=0,IF((D10+N10-O10)<0,ABS(D10+N10-O10),0),IF((N10-E10-O10)<0,ABS(N10-E10-O10),0)),2) -> 0
A11: 5 | B11: Семко Л.І. | C11: 1005 | D11: 2643.87 | E11: 0 | F11: 0 | G11: 28.34 | H11: 0 | I11: =W$1 -> 4.1 | J11: =ROUND(G11*I11,2) -> 116.19 | N11: =ROUND((G11*I11)-K11-L11-M11,2) -> 116.19 | P11: =ROUND(IF(D11=0,IF((N11-E11-O11)>0,(N11-E11-O11),0),IF((D11+N11-O11)>0,(D11+N11-O11),0)),2) -> 2760.06 | Q11: =ROUND(IF(E11=0,IF((D11+N11-O11)<0,ABS(D11+N11-O11),0),IF((N11-E11-O11)<0,ABS(N11-E11-O11),0)),2) -> 0
A12: 5 | B12: Гаркуша Н.І. | C12: 1005-а | D12: 809.26 | E12: 0 | F12: 0 | G12: 36.66 | H12: 0 | I12: =W$1 -> 4.1 | J12: =ROUND(G12*I12,2) -> 150.31 | N12: =ROUND((G12*I12)-K12-L12-M12,2) -> 150.31 | P12: =ROUND(IF(D12=0,IF((N12-E12-O12)>0,(N12-E12-O12),0),IF((D12+N12-O12)>0,(D12+N12-O12),0)),2) -> 959.57 | Q12: =ROUND(IF(E12=0,IF((D12+N12-O12)<0,ABS(D12+N12-O12),0),IF((N12-E12-O12)<0,ABS(N12-E12-O12),0)),2) -> 0
A13: 6 | B13: Андріяшев В.М | C13: 1006 | D13: 134.56 | E13: 0 | F13: 0 | G13: 49.8 | H13: 0 | I13: =W$1 -> 4.1 | J13: =ROUND(G13*I13,2) -> 204.18 | N13: =ROUND((G13*I13)-K13-L13-M13,2) -> 204.18 | P13: =ROUND(IF(D13=0,IF((N13-E13-O13)>0,(N13-E13-O13),0),IF((D13+N13-O13)>0,(D13+N13-O13),0)),2) -> 338.74 | Q13: =ROUND(IF(E13=0,IF((D13+N13-O13)<0,ABS(D13+N13-O13),0),IF((N13-E13-O13)<0,ABS(N13-E13-O13),0)),2) -> 0
A14: 7 | B14: Старчикова О.М. | C14: 1007 | D14: 142.07 | E14: 0 | F14: 0 | G14: 34.65 | H14: 0 | I14: =W$1 -> 4.1 | J14: =ROUND(G14*I14,2) -> 142.07 | N14: =ROUND((G14*I14)-K14-L14-M14,2) -> 142.07 | P14: =ROUND(IF(D14=0,IF((N14-E14-O14)>0,(N14-E14-O14),0),IF((D14+N14-O14)>0,(D14+N14-O14),0)),2) -> 284.14 | Q14: =ROUND(IF(E14=0,IF((D14+N14-O14)<0,ABS(D14+N14-O14),0),IF((N14-E14-O14)<0,ABS(N14-E14-O14),0)),2) -> 0
A15: 8 | B15: Безер Т.М | C15: 1008 | D15: 0 | E15: 7.03 | F15: 0 | G15: 62.14 | H15: 0 | I15: =W$1 -> 4.1 | J15: =ROUND(G15*I15,2) -> 254.77 | N15: =ROUND((G15*I15)-K15-L15-M15,2) -> 254.77 | P15: =ROUND(IF(D15=0,IF((N15-E15-O15)>0,(N15-E15-O15),0),IF((D15+N15-O15)>0,(D15+N15-O15),0)),2) -> 247.74 | Q15: =ROUND(IF(E15=0,IF((D15+N15-O15)<0,ABS(D15+N15-O15),0),IF((N15-E15-O15)<0,ABS(N15-E15-O15),0)),2) -> 0
A16: 9 | B16: Решетило М.М | C16: 1009 | D16: 801.72 | E16: 0 | F16: 0 | G16: 65.16 | H16: 0 | I16: =W$1 -> 4.1 | J16: =ROUND(G16*I16,2) -> 267.16 | N16: =ROUND((G16*I16)-K16-L16-M16,2) -> 267.16 | P16: =ROUND(IF(D16=0,IF((N16-E16-O16)>0,(N16-E16-O16),0),IF((D16+N16-O16)>0,(D16+N16-O16),0)),2) -> 1068.88 | Q16: =ROUND(IF(E16=0,IF((D16+N16-O16)<0,ABS(D16+N16-O16),0),IF((N16-E16-O16)<0,ABS(N16-E16-O16),0)),2) -> 0
A17: 10 | B17: Фесенко О.В. | C17: 1010 | D17: 4876.69 | E17: 0 | F17: 0 | G17: 50.1 | H17: 0 | I17: =W$1 -> 4.1 | J17: =ROUND(G17*I17,2) -> 205.41 | N17: =ROUND((G17*I17)-K17-L17-M17,2) -> 205.41 | P17: =ROUND(IF(D17=0,IF((N17-E17-O17)>0,(N17-E17-O17),0),IF((D17+N17-O17)>0,(D17+N17-O17),0)),2) -> 5082.1 | Q17: =ROUND(IF(E17=0,IF((D17+N17-O17)<0,ABS(D17+N17-O17),0),IF((N17-E17-O17)<0,ABS(N17-E17-O17),0)),2) -> 0
A18: 11 | B18: Петренко О.М. | C18: 1011 | D18: 1648.2 | E18: 0 | F18: 0 | G18: 35.2 | H18: 0 | I18: =W$1 -> 4.1 | J18: =ROUND(G18*I18,2) -> 144.32 | N18: =ROUND((G18*I18)-K18-L18-M18,2) -> 144.32 | O18: 100 | P18: =ROUND(IF(D18=0,IF((N18-E18-O18)>0,(N18-E18-O18),0),IF((D18+N18-O18)>0,(D18+N18-O18),0)),2) -> 1692.52 | Q18: =ROUND(IF(E18=0,IF((D18+N18-O18)<0,ABS(D18+N18-O18),0),IF((N18-E18-O18)<0,ABS(N18-E18-O18),0)),2) -> 0
A19: 12 | B19: Зеленюк А.Д | C19: 1012 | D19: 12179.61 | E19: 0 | F19: 0 | G19: 62.78 | H19: 0 | I19: =W$1 -> 4.1 | J19: =ROUND(G19*I19,2) -> 257.4 | N19: =ROUND((G19*I19)-K19-L19-M19,2) -> 257.4 | P19: =ROUND(IF(D19=0,IF((N19-E19-O19)>0,(N19-E19-O19),0),IF((D19+N19-O19)>0,(D19+N19-O19),0)),2) -> 12437.01 | Q19: =ROUND(IF(E19=0,IF((D19+N19-O19)<0,ABS(D19+N19-O19),0),IF((N19-E19-O19)<0,ABS(N19-E19-O19),0)),2) -> 0
A20: 13 | B20: Вовк І.В | C20: 1013 | D20: 5199.06 | E20: 0 | F20: 0 | G20: 28.23 | H20: 0 | I20: =W$1 -> 4.1 | J20: =ROUND(G20*I20,2) -> 115.74 | N20: =ROUND((G20*I20)-K20-L20-M20,2) -> 115.74 | P20: =ROUND(IF(D20=0,IF((N20-E20-O20)>0,(N20-E20-O20),0),IF((D20+N20-O20)>0,(D20+N20-O20),0)),2) -> 5314.8 | Q20: =ROUND(IF(E20=0,IF((D20+N20-O20)<0,ABS(D20+N20-O20),0),IF((N20-E20-O20)<0,ABS(N20-E20-O20),0)),2) -> 0
A21: 13 | B21: Романовський В.М | C21: 1013-а | D21: 5451.68 | E21: 0 | F21: 0 | G21: 37.84 | H21: 0 | I21: =W$1 -> 4.1 | J21: =ROUND(G21*I21,2) -> 155.14 | N21: =ROUND((G21*I21)-K21-L21-M21,2) -> 155.14 | P21: =ROUND(IF(D21=0,IF((N21-E21-O21)>0,(N21-E21-O21),0),IF((D21+N21-O21)>0,(D21+N21-O21),0)),2) -> 5606.82 | Q21: =ROUND(IF(E21=0,IF((D21+N21-O21)<0,ABS(D21+N21-O21),0),IF((N21-E21-O21)<0,ABS(N21-E21-O21),0)),2) -> 0
A22: 14 | B22: Ряба Л.І | C22: 1014 | D22: 276.56 | E22: 0 | F22: 0 | G22: 49.24 | H22: 0 | I22: =W$1 -> 4.1 | J22: =ROUND(G22*I22,2) -> 201.88 | N22: =ROUND((G22*I22)-K22-L22-M22,2) -> 201.88 | O22: 210 | P22: =ROUND(IF(D22=0,IF((N22-E22-O22)>0,(N22-E22-O22),0),IF((D22+N22-O22)>0,(D22+N22-O22),0)),2) -> 268.44 | Q22: =ROUND(IF(E22=0,IF((D22+N22-O22)<0,ABS(D22+N22-O22),0),IF((N22-E22-O22)<0,ABS(N22-E22-O22),0)),2) -> 0
A23: 15 | B23: Кас'янова О.А. | C23: 1015 | D23: 435.8 | E23: 0 | F23: 0 | G23: 35.1 | H23: 0 | I23: =W$1 -> 4.1 | J23: =ROUND(G23*I23,2) -> 143.91 | N23: =ROUND((G23*I23)-K23-L23-M23,2) -> 143.91 | P23: =ROUND(IF(D23=0,IF((N23-E23-O23)>0,(N23-E23-O23),0),IF((D23+N23-O23)>0,(D23+N23-O23),0)),2) -> 579.71 | Q23: =ROUND(IF(E23=0,IF((D23+N23-O23)<0,ABS(D23+N23-O23),0),IF((N23-E23-O23)<0,ABS(N23-E23-O23),0)),2) -> 0
A24: 16 | B24: Корякіна М.В. | C24: 1016 | D24: 5207.58 | E24: 0 | F24: 0 | G24: 61.9 | H24: 0 | I24: =W$1 -> 4.1 | J24: =ROUND(G24*I24,2) -> 253.79 | N24: =ROUND((G24*I24)-K24-L24-M24,2) -> 253.79 | O24: 507.58 | P24: =ROUND(IF(D24=0,IF((N24-E24-O24)>0,(N24-E24-O24),0),IF((D24+N24-O24)>0,(D24+N24-O24),0)),2) -> 4953.79 | Q24: =ROUND(IF(E24=0,IF((D24+N24-O24)<0,ABS(D24+N24-O24),0),IF((N24-E24-O24)<0,ABS(N24-E24-O24),0)),2) -> 0
A25: 17 | B25: Сокерчак А.В. | C25: 1017 | D25: 271.83 | E25: 0 | F25: 0 | G25: 66.3 | H25: 0 | I25: =W$1 -> 4.1 | J25: =ROUND(G25*I25,2) -> 271.83 | N25: =ROUND((G25*I25)-K25-L25-M25,2) -> 271.83 | P25: =ROUND(IF(D25=0,IF((N25-E25-O25)>0,(N25-E25-O25),0),IF((D25+N25-O25)>0,(D25+N25-O25),0)),2) -> 543.66 | Q25: =ROUND(IF(E25=0,IF((D25+N25-O25)<0,ABS(D25+N25-O25),0),IF((N25-E25-O25)<0,ABS(N25-E25-O25),0)),2) -> 0
A26: 18 | B26: Кравченко В.А | C26: 1018 | D26: 211.07 | E26: 0 | F26: 0 | G26: 51.48 | H26: 0 | I26: =W$1 -> 4.1 | J26: =ROUND(G26*I26,2) -> 211.07 | N26: =ROUND((G26*I26)-K26-L26-M26,2) -> 211.07 | O26: 211.07 | P26: =ROUND(IF(D26=0,IF((N26-E26-O26)>0,(N26-E26-O26),0),IF((D26+N26-O26)>0,(D26+N26-O26),0)),2) -> 211.07 | Q26: =ROUND(IF(E26=0,IF((D26+N26-O26)<0,ABS(D26+N26-O26),0),IF((N26-E26-O26)<0,ABS(N26-E26-O26),0)),2) -> 0
A27: 19 | B27: Чичикало А.С | C27: 1019 | D27: 0 | E27: 570.86 | F27: 0 | G27: 35.1 | H27: 0 | I27: =W$1 -> 4.1 | J27: =ROUND(G27*I27,2) -> 143.91 | N27: =ROUND((G27*I27)-K27-L27-M27,2) -> 143.91 | P27: =ROUND(IF(D27=0,IF((N27-E27-O27)>0,(N27-E27-O27),0),IF((D27+N27-O27)>0,(D27+N27-O27),0)),2) -> 0 | Q27: =ROUND(IF(E27=0,IF((D27+N27-O27)<0,ABS(D27+N27-O27),0),IF((N27-E27-O27)<0,ABS(N27-E27-O27),0)),2) -> 426.95
A28: 20 | B28: Сільващук А.А | C28: 1020 | D28: 0 | E28: 0 | F28: 0 | G28: 62.7 | H28: 0 | I28: =W$1 -> 4.1 | J28: =ROUND(G28*I28,2) -> 257.07 | N28: =ROUND((G28*I28)-K28-L28-M28,2) -> 257.07 | P28: =ROUND(IF(D28=0,IF((N28-E28-O28)>0,(N28-E28-O28),0),IF((D28+N28-O28)>0,(D28+N28-O28),0)),2) -> 257.07 | Q28: =ROUND(IF(E28=0,IF((D28+N28-O28)<0,ABS(D28+N28-O28),0),IF((N28-E28-O28)<0,ABS(N28-E28-O28),0)),2) -> 0
A29: 21 | B29: Стеценко Г.М | C29: 1021 | D29: 267.81 | E29: 0 | F29: 0 | G29: 65.32 | H29: 0 | I29: =W$1 -> 4.1 | J29: =ROUND(G29*I29,2) -> 267.81 | N29: =ROUND((G29*I29)-K29-L29-M29,2) -> 267.81 | P29: =ROUND(IF(D29=0,IF((N29-E29-O29)>0,(N29-E29-O29),0),IF((D29+N29-O29)>0,(D29+N29-O29),0)),2) -> 535.62 | Q29: =ROUND(IF(E29=0,IF((D29+N29-O29)<0,ABS(D29+N29-O29),0),IF((N29-E29-O29)<0,ABS(N29-E29-O29),0)),2) -> 0
A30: 22 | B30: Кирдячкіна П.А | C30: 1022 | D30: 0 | E30: 50.52 | F30: 0 | G30: 49.7 | H30: 0 | I30: =W$1 -> 4.1 | J30: =ROUND(G30*I30,2) -> 203.77 | N30: =ROUND((G30*I30)-K30-L30-M30,2) -> 203.77 | P30: =ROUND(IF(D30=0,IF((N30-E30-O30)>0,(N30-E30-O30),0),IF((D30+N30-O30)>0,(D30+N30-O30),0)),2) -> 153.25 | Q30: =ROUND(IF(E30=0,IF((D30+N30-O30)<0,ABS(D30+N30-O30),0),IF((N30-E30-O30)<0,ABS(N30-E30-O30),0)),2) -> 0
A31: 23 | B31: Фоміченко Л.А | C31: 1023 | D31: 3680.76 | E31: 0 | F31: 0 | G31: 35.1 | H31: 0 | I31: =W$1 -> 4.1 | J31: =ROUND(G31*I31,2) -> 143.91 | N31: =ROUND((G31*I31)-K31-L31-M31,2) -> 143.91 | P31: =ROUND(IF(D31=0,IF((N31-E31-O31)>0,(N31-E31-O31),0),IF((D31+N31-O31)>0,(D31+N31-O31),0)),2) -> 3824.67 | Q31: =ROUND(IF(E31=0,IF((D31+N31-O31)<0,ABS(D31+N31-O31),0),IF((N31-E31-O31)<0,ABS(N31-E31-O31),0)),2) -> 0
A32: 24 | B32: Сердюк А.Г | C32: 1024 | D32: 255.42 | E32: 0 | F32: 0 | G32: 62.31 | H32: 0 | I32: =W$1 -> 4.1 | J32: =ROUND(G32*I32,2) -> 255.47 | N32: =ROUND((G32*I32)-K32-L32-M32,2) -> 255.47 | P32: =ROUND(IF(D32=0,IF((N32-E32-O32)>0,(N32-E32-O32),0),IF((D32+N32-O32)>0,(D32+N32-O32),0)),2) -> 510.89 | Q32: =ROUND(IF(E32=0,IF((D32+N32-O32)<0,ABS(D32+N32-O32),0),IF((N32-E32-O32)<0,ABS(N32-E32-O32),0)),2) -> 0
A33: 25 | B33: Михальченко Г.М | C33: 1025 | D33: 12387.24 | E33: 0 | F33: 0 | G33: 65.04 | H33: 0 | I33: =W$1 -> 4.1 | J33: =ROUND(G33*I33,2) -> 266.66 | N33: =ROUND((G33*I33)-K33-L33-M33,2) -> 266.66 | P33: =ROUND(IF(D33=0,IF((N33-E33-O33)>0,(N33-E33-O33),0),IF((D33+N33-O33)>0,(D33+N33-O33),0)),2) -> 12653.9 | Q33: =ROUND(IF(E33=0,IF((D33+N33-O33)<0,ABS(D33+N33-O33),0),IF((N33-E33-O33)<0,ABS(N33-E33-O33),0)),2) -> 0
A34: 26 | B34: Замуховська Я.С | C34: 1026 | D34: 408.36 | E34: 0 | F34: 0 | G34: 49.8 | H34: 0 | I34: =W$1 -> 4.1 | J34: =ROUND(G34*I34,2) -> 204.18 | N34: =ROUND((G34*I34)-K34-L34-M34,2) -> 204.18 | P34: =ROUND(IF(D34=0,IF((N34-E34-O34)>0,(N34-E34-O34),0),IF((D34+N34-O34)>0,(D34+N34-O34),0)),2) -> 612.54 | Q34: =ROUND(IF(E34=0,IF((D34+N34-O34)<0,ABS(D34+N34-O34),0),IF((N34-E34-O34)<0,ABS(N34-E34-O34),0)),2) -> 0
A35: 27 | B35: Мержиєвська Г.К | C35: 1027 | D35: 288.4 | E35: 0 | F35: 0 | G35: 35.17 | H35: 0 | I35: =W$1 -> 4.1 | J35: =ROUND(G35*I35,2) -> 144.2 | N35: =ROUND((G35*I35)-K35-L35-M35,2) -> 144.2 | P35: =ROUND(IF(D35=0,IF((N35-E35-O35)>0,(N35-E35-O35),0),IF((D35+N35-O35)>0,(D35+N35-O35),0)),2) -> 432.6 | Q35: =ROUND(IF(E35=0,IF((D35+N35-O35)<0,ABS(D35+N35-O35),0),IF((N35-E35-O35)<0,ABS(N35-E35-O35),0)),2) -> 0
A36: 28 | B36: Кулакова Л.В. | C36: 1028 | D36: 0 | E36: 0 | F36: 0 | G36: 62.47 | H36: 0 | I36: =W$1 -> 4.1 | J36: =ROUND(G36*I36,2) -> 256.13 | N36: =ROUND((G36*I36)-K36-L36-M36,2) -> 256.13 | P36: =ROUND(IF(D36=0,IF((N36-E36-O36)>0,(N36-E36-O36),0),IF((D36+N36-O36)>0,(D36+N36-O36),0)),2) -> 256.13 | Q36: =ROUND(IF(E36=0,IF((D36+N36-O36)<0,ABS(D36+N36-O36),0),IF((N36-E36-O36)<0,ABS(N36-E36-O36),0)),2) -> 0
A37: 29 | B37: Бочаров В.Л. | C37: 1029 | D37: 6983.52 | E37: 0 | F37: 0 | G37: 65.75 | H37: 0 | I37: =W$1 -> 4.1 | J37: =ROUND(G37*I37,2) -> 269.58 | N37: =ROUND((G37*I37)-K37-L37-M37,2) -> 269.58 | P37: =ROUND(IF(D37=0,IF((N37-E37-O37)>0,(N37-E37-O37),0),IF((D37+N37-O37)>0,(D37+N37-O37),0)),2) -> 7253.1 | Q37: =ROUND(IF(E37=0,IF((D37+N37-O37)<0,ABS(D37+N37-O37),0),IF((N37-E37-O37)<0,ABS(N37-E37-O37),0)),2) -> 0
A38: 30 | B38: Лучков В.Л. | C38: 1030 | D38: 9568.55 | E38: 0 | F38: 0 | G38: 49.7 | H38: 0 | I38: =W$1 -> 4.1 | J38: =ROUND(G38*I38,2) -> 203.77 | N38: =ROUND((G38*I38)-K38-L38-M38,2) -> 203.77 | P38: =ROUND(IF(D38=0,IF((N38-E38-O38)>0,(N38-E38-O38),0),IF((D38+N38-O38)>0,(D38+N38-O38),0)),2) -> 9772.32 | Q38: =ROUND(IF(E38=0,IF((D38+N38-O38)<0,ABS(D38+N38-O38),0),IF((N38-E38-O38)<0,ABS(N38-E38-O38),0)),2) -> 0
... A45: 37 | B45: Гурова О.М. | C45: 2037 | D45: 0 | E45: 316.37 | F45: 0 | G45: 62.2 | H45: 0 | I45: =W$1 -> 4.1 | J45: =ROUND(G45*I45,2) -> 255.02 | N45: =ROUND((G45*I45)-K45-L45-M45,2) -> 255.02 | P45: =ROUND(IF(D45=0,IF((N45-E45-O45)>0,(N45-E45-O45),0),IF((D45+N45-O45)>0,(D45+N45-O45),0)),2) -> 0 | Q45: =ROUND(IF(E45=0,IF((D45+N45-O45)<0,ABS(D45+N45-O45),0),IF((N45-E45-O45)<0,ABS(N45-E45-O45),0)),2) -> 61.35
A46: 38 | B46: Федорова В.І. | C46: 2038 | D46: 143.09 | E46: 0 | F46: 0 | G46: 34.9 | H46: 0 | I46: =W$1 -> 4.1 | J46: =ROUND(G46*I46,2) -> 143.09 | N46: =ROUND((G46*I46)-K46-L46-M46,2) -> 143.09 | O46: 500 | P46: =ROUND(IF(D46=0,IF((N46-E46-O46)>0,(N46-E46-O46),0),IF((D46+N46-O46)>0,(D46+N46-O46),0)),2) -> 0 | Q46: =ROUND(IF(E46=0,IF((D46+N46-O46)<0,ABS(D46+N46-O46),0),IF((N46-E46-O46)<0,ABS(N46-E46-O46),0)),2) -> 213.82
A47: 39 | B47: Лаптєв В.І. | C47: 2039 | D47: 200.08 | E47: 0 | F47: 0 | G47: 48.8 | H47: 0 | I47: =W$1 -> 4.1 | J47: =ROUND(G47*I47,2) -> 200.08 | N47: =ROUND((G47*I47)-K47-L47-M47,2) -> 200.08 | O47: 200.08 | P47: =ROUND(IF(D47=0,IF((N47-E47-O47)>0,(N47-E47-O47),0),IF((D47+N47-O47)>0,(D47+N47-O47),0)),2) -> 200.08 | Q47: =ROUND(IF(E47=0,IF((D47+N47-O47)<0,ABS(D47+N47-O47),0),IF((N47-E47-O47)<0,ABS(N47-E47-O47),0)),2) -> 0
A48: 40 | B48: Тимощук О.Є. | C48: 2040 | D48: 234.93 | E48: 0 | F48: 0 | G48: 57.3 | H48: 0 | I48: =W$1 -> 4.1 | J48: =ROUND(G48*I48,2) -> 234.93 | N48: =ROUND((G48*I48)-K48-L48-M48,2) -> 234.93 | O48: 234.93 | P48: =ROUND(IF(D48=0,IF((N48-E48-O48)>0,(N48-E48-O48),0),IF((D48+N48-O48)>0,(D48+N48-O48),0)),2) -> 234.93 | Q48: =ROUND(IF(E48=0,IF((D48+N48-O48)<0,ABS(D48+N48-O48),0),IF((N48-E48-O48)<0,ABS(N48-E48-O48),0)),2) -> 0
...

Sheet лютий
A1: ОСББ "Карбишева - 22" | N1: 37465042
B2: Відомість нарахувань та оплати мешканців за утримання будинку
B3: у лютому 2026 року
A6: № кв. | B6: ПІБ | C6: Особ. рах. | D6: Д-Т | E6: К-Т | F6: Пільга % | G6: Заг.площа | H6: Пільг. Площа | I6: Тариф | J6: 100% нарах. | K6: Пільгова сума | L6: сплачені суми пільг за реєстрами | M6: Коригування | N6: До сплати | O6: Сплачено | P6: Д-Т | Q6: К-Т
A7: 1 | B7: =січень!B7 -> Бережний В.М. | C7: 1001 | D7: =січень!P7 -> 1086.62 | E7: =січень!Q7 -> 0 | F7: =січень!F7 -> 0 | G7: =січень!G7 -> 64.26 | H7: =січень!H7 -> 0 | I7: =січень!I7 -> 4.1 | J7: =ROUND(G7*I7,2) -> 263.47 | N7: =ROUND((G7*I7)-K7-L7-M7,2) -> 263.47 | P7: =ROUND(IF(D7=0,IF((N7-E7-O7)>0,(N7-E7-O7),0),IF((D7+N7-O7)>0,(D7+N7-O7),0)),2) -> 1350.09 | Q7: =ROUND(IF(E7=0,IF((D7+N7-O7)<0,ABS(D7+N7-O7),0),IF((N7-E7-O7)<0,ABS(N7-E7-O7),0)),2) -> 0
A8: 2 | B8: =січень!B8 -> Старикова Т.О. | C8: 1002 | D8: =січень!P8 -> 199.71 | E8: =січень!Q8 -> 0 | F8: =січень!F8 -> 0 | G8: =січень!G8 -> 48.71 | H8: =січень!H8 -> 0 | I8: =січень!I8 -> 4.1 | J8: =ROUND(G8*I8,2) -> 199.71 | N8: =ROUND((G8*I8)-K8-L8-M8,2) -> 199.71 | P8: =ROUND(IF(D8=0,IF((N8-E8-O8)>0,(N8-E8-O8),0),IF((D8+N8-O8)>0,(D8+N8-O8),0)),2) -> 399.42 | Q8: =ROUND(IF(E8=0,IF((D8+N8-O8)<0,ABS(D8+N8-O8),0),IF((N8-E8-O8)<0,ABS(N8-E8-O8),0)),2) -> 0
A9: 3 | B9: =січень!B9 -> Мазур Т.В. | C9: 1003 | D9: =січень!P9 -> 287 | E9: =січень!Q9 -> 0 | F9: =січень!F9 -> 0 | G9: =січень!G9 -> 35 | H9: =січень!H9 -> 0 | I9: =січень!I9 -> 4.1 | J9: =ROUND(G9*I9,2) -> 143.5 | N9: =ROUND((G9*I9)-K9-L9-M9,2) -> 143.5 | P9: =ROUND(IF(D9=0,IF((N9-E9-O9)>0,(N9-E9-O9),0),IF((D9+N9-O9)>0,(D9+N9-O9),0)),2) -> 430.5 | Q9: =ROUND(IF(E9=0,IF((D9+N9-O9)<0,ABS(D9+N9-O9),0),IF((N9-E9-O9)<0,ABS(N9-E9-O9),0)),2) -> 0
A10: 4 | B10: =січень!B10 -> Сокол О.В. | C10: 1004 | D10: =січень!P10 -> 0 | E10: =січень!Q10 -> 0 | F10: =січень!F10 -> 0 | G10: =січень!G10 -> 61.6 | H10: =січень!H10 -> 0 | I10: =січень!I10 -> 4.1 | J10: =ROUND(G10*I10,2) -> 252.56 | N10: =ROUND((G10*I10)-K10-L10-M10,2) -> 252.56 | P10: =ROUND(IF(D10=0,IF((N10-E10-O10)>0,(N10-E10-O10),0),IF((D10+N10-O10)>0,(D10+N10-O10),0)),2) -> 252.56 | Q10: =ROUND(IF(E10=0,IF((D10+N10-O10)<0,ABS(D10+N10-O10),0),IF((N10-E10-O10)<0,ABS(N10-E10-O10),0)),2) -> 0
A11: 5 | B11: =січень!B11 -> Семко Л.І. | C11: 1005 | D11: =січень!P11 -> 2760.06 | E11: =січень!Q11 -> 0 | F11: =січень!F11 -> 0 | G11: =січень!G11 -> 28.34 | H11: =січень!H11 -> 0 | I11: =січень!I11 -> 4.1 | J11: =ROUND(G11*I11,2) -> 116.19 | N11: =ROUND((G11*I11)-K11-L11-M11,2) -> 116.19 | P11: =ROUND(IF(D11=0,IF((N11-E11-O11)>0,(N11-E11-O11),0),IF((D11+N11-O11)>0,(D11+N11-O11),0)),2) -> 2876.25 | Q11: =ROUND(IF(E11=0,IF((D11+N11-O11)<0,ABS(D11+N11-O11),0),IF((N11-E11-O11)<0,ABS(N11-E11-O11),0)),2) -> 0
A12: 5 | B12: =січень!B12 -> Гаркуша Н.І. | C12: 1005-а | D12: =січень!P12 -> 959.57 | E12: =січень!Q12 -> 0 | F12: =січень!F12 -> 0 | G12: =січень!G12 -> 36.66 | H12: =січень!H12 -> 0 | I12: =січень!I12 -> 4.1 | J12: =ROUND(G12*I12,2) -> 150.31 | N12: =ROUND((G12*I12)-K12-L12-M12,2) -> 150.31 | P12: =ROUND(IF(D12=0,IF((N12-E12-O12)>0,(N12-E12-O12),0),IF((D12+N12-O12)>0,(D12+N12-O12),0)),2) -> 1109.88 | Q12: =ROUND(IF(E12=0,IF((D12+N12-O12)<0,ABS(D12+N12-O12),0),IF((N12-E12-O12)<0,ABS(N12-E12-O12),0)),2) -> 0
A13: 6 | B13: =січень!B13 -> Андріяшев В.М | C13: 1006 | D13: =січень!P13 -> 338.74 | E13: =січень!Q13 -> 0 | F13: =січень!F13 -> 0 | G13: =січень!G13 -> 49.8 | H13: =січень!H13 -> 0 | I13: =січень!I13 -> 4.1 | J13: =ROUND(G13*I13,2) -> 204.18 | N13: =ROUND((G13*I13)-K13-L13-M13,2) -> 204.18 | P13: =ROUND(IF(D13=0,IF((N13-E13-O13)>0,(N13-E13-O13),0),IF((D13+N13-O13)>0,(D13+N13-O13),0)),2) -> 542.92 | Q13: =ROUND(IF(E13=0,IF((D13+N13-O13)<0,ABS(D13+N13-O13),0),IF((N13-E13-O13)<0,ABS(N13-E13-O13),0)),2) -> 0
A14: 7 | B14: =січень!B14 -> Старчикова О.М. | C14: 1007 | D14: =січень!P14 -> 284.14 | E14: =січень!Q14 -> 0 | F14: =січень!F14 -> 0 | G14: =січень!G14 -> 34.65 | H14: =січень!H14 -> 0 | I14: =січень!I14 -> 4.1 | J14: =ROUND(G14*I14,2) -> 142.07 | N14: =ROUND((G14*I14)-K14-L14-M14,2) -> 142.07 | P14: =ROUND(IF(D14=0,IF((N14-E14-O14)>0,(N14-E14-O14),0),IF((D14+N14-O14)>0,(D14+N14-O14),0)),2) -> 426.21 | Q14: =ROUND(IF(E14=0,IF((D14+N14-O14)<0,ABS(D14+N14-O14),0),IF((N14-E14-O14)<0,ABS(N14-E14-O14),0)),2) -> 0
A15: 8 | B15: =січень!B15 -> Безер Т.М | C15: 1008 | D15: =січень!P15 -> 247.74 | E15: =січень!Q15 -> 0 | F15: =січень!F15 -> 0 | G15: =січень!G15 -> 62.14 | H15: =січень!H15 -> 0 | I15: =січень!I15 -> 4.1 | J15: =ROUND(G15*I15,2) -> 254.77 | N15: =ROUND((G15*I15)-K15-L15-M15,2) -> 254.77 | P15: =ROUND(IF(D15=0,IF((N15-E15-O15)>0,(N15-E15-O15),0),IF((D15+N15-O15)>0,(D15+N15-O15),0)),2) -> 502.51 | Q15: =ROUND(IF(E15=0,IF((D15+N15-O15)<0,ABS(D15+N15-O15),0),IF((N15-E15-O15)<0,ABS(N15-E15-O15),0)),2) -> 0
A16: 9 | B16: =січень!B16 -> Решетило М.М | C16: 1009 | D16: =січень!P16 -> 1068.88 | E16: =січень!Q16 -> 0 | F16: =січень!F16 -> 0 | G16: =січень!G16 -> 65.16 | H16: =січень!H16 -> 0 | I16: =січень!I16 -> 4.1 | J16: =ROUND(G16*I16,2) -> 267.16 | N16: =ROUND((G16*I16)-K16-L16-M16,2) -> 267.16 | P16: =ROUND(IF(D16=0,IF((N16-E16-O16)>0,(N16-E16-O16),0),IF((D16+N16-O16)>0,(D16+N16-O16),0)),2) -> 1336.04 | Q16: =ROUND(IF(E16=0,IF((D16+N16-O16)<0,ABS(D16+N16-O16),0),IF((N16-E16-O16)<0,ABS(N16-E16-O16),0)),2) -> 0
A17: 10 | B17: =січень!B17 -> Фесенко О.В. | C17: 1010 | D17: =січень!P17 -> 5082.1 | E17: =січень!Q17 -> 0 | F17: =січень!F17 -> 0 | G17: =січень!G17 -> 50.1 | H17: =січень!H17 -> 0 | I17: =січень!I17 -> 4.1 | J17: =ROUND(G17*I17,2) -> 205.41 | N17: =ROUND((G17*I17)-K17-L17-M17,2) -> 205.41 | P17: =ROUND(IF(D17=0,IF((N17-E17-O17)>0,(N17-E17-O17),0),IF((D17+N17-O17)>0,(D17+N17-O17),0)),2) -> 5287.51 | Q17: =ROUND(IF(E17=0,IF((D17+N17-O17)<0,ABS(D17+N17-O17),0),IF((N17-E17-O17)<0,ABS(N17-E17-O17),0)),2) -> 0
A18: 11 | B18: =січень!B18 -> Петренко О.М. | C18: 1011 | D18: =січень!P18 -> 1692.52 | E18: =січень!Q18 -> 0 | F18: =січень!F18 -> 0 | G18: =січень!G18 -> 35.2 | H18: =січень!H18 -> 0 | I18: =січень!I18 -> 4.1 | J18: =ROUND(G18*I18,2) -> 144.32 | N18: =ROUND((G18*I18)-K18-L18-M18,2) -> 144.32 | P18: =ROUND(IF(D18=0,IF((N18-E18-O18)>0,(N18-E18-O18),0),IF((D18+N18-O18)>0,(D18+N18-O18),0)),2) -> 1836.84 | Q18: =ROUND(IF(E18=0,IF((D18+N18-O18)<0,ABS(D18+N18-O18),0),IF((N18-E18-O18)<0,ABS(N18-E18-O18),0)),2) -> 0
... A221: 213 | B221: =січень!B221 -> Корнюшенко О.О. | C221: 60213 | D221: =січень!P221 -> 7779 | E221: =січень!Q221 -> 0 | F221: =січень!F221 -> 0 | G221: =січень!G221 -> 62 | H221: =січень!H221 -> 0 | I221: =січень!I221 -> 4.1 | J221: =ROUND(G221*I221,2) -> 254.2 | N221: =ROUND((G221*I221)-K221-L221-M221,2) -> 254.2 | P221: =ROUND(IF(D221=0,IF((N221-E221-O221)>0,(N221-E221-O221),0),IF((D221+N221-O221)>0,(D221+N221-O221),0)),2) -> 8033.2 | Q221: =ROUND(IF(E221=0,IF((D221+N221-O221)<0,ABS(D221+N221-O221),0),IF((N221-E221-O221)<0,ABS(N221-E221-O221),0)),2) -> 0
D222: =SUM(D7:D221) -> 812245.35 | E222: =SUM(E7:E221) -> 5240.47 | G222: =SUM(G7:G221) -> 11652.42 | H222: =SUM(H7:H221) -> 0 | J222: =SUM(J7:J221) -> 47774.99 | K222: =SUM(K7:K221) -> 0 | L222: =SUM(L7:L221) -> 0 | M222: =SUM(M7:M221) -> 0 | N222: =SUM(N7:N221) -> 47774.99 | O222: =SUM(O7:O221) -> 0 | P222: =SUM(P7:P221) -> 858443.06 | Q222: =SUM(Q7:Q221) -> 3663.19
D223: =D222-E222 -> 807004.88 | P223: =P222-Q222 -> 854779.87 | V223: 0
V224: 0

Sheet березень
A1: ОСББ "Карбишева - 22" | N1: 37465042
B2: Відомість нарахувань та оплати мешканців за утримання будинку
B3: у березні 2026 року
A6: № кв. | B6: ПІБ | C6: Особ. рах. | D6: Д-Т | E6: К-Т | F6: Пільга % | G6: Заг.площа | H6: Пільг. Площа | I6: Тариф | J6: 100% нарах. | K6: Пільгова сума | L6: сплачені суми пільг за реєстрами | M6: Коригування | N6: До сплати | O6: Сплачено | P6: Д-Т | Q6: К-Т
A7: 1 | B7: =лютий!B7 -> Бережний В.М. | C7: 1001 | D7: =лютий!P7 -> 1350.09 | E7: =лютий!Q7 -> 0 | F7: =лютий!F7 -> 0 | G7: =лютий!G7 -> 64.26 | H7: =лютий!H7 -> 0 | I7: =лютий!I7 -> 4.1 | J7: =ROUND(G7*I7,2) -> 263.47 | N7: =ROUND((G7*I7)-K7-L7-M7,2) -> 263.47 | P7: =ROUND(IF(D7=0,IF((N7-E7-O7)>0,(N7-E7-O7),0),IF((D7+N7-O7)>0,(D7+N7-O7),0)),2) -> 1613.56 | Q7: =ROUND(IF(E7=0,IF((D7+N7-O7)<0,ABS(D7+N7-O7),0),IF((N7-E7-O7)<0,ABS(N7-E7-O7),0)),2) -> 0
A8: 2 | B8: =лютий!B8 -> Старикова Т.О. | C8: 1002 | D8: =лютий!P8 -> 399.42 | E8: =лютий!Q8 -> 0 | F8: =лютий!F8 -> 0 | G8: =лютий!G8 -> 48.71 | H8: =лютий!H8 -> 0 | I8: =лютий!I8 -> 4.1 | J8: =ROUND(G8*I8,2) -> 199.71 | N8: =ROUND((G8*I8)-K8-L8-M8,2) -> 199.71 | P8: =ROUND(IF(D8=0,IF((N8-E8-O8)>0,(N8-E8-O8),0),IF((D8+N8-O8)>0,(D8+N8-O8),0)),2) -> 599.13 | Q8: =ROUND(IF(E8=0,IF((D8+N8-O8)<0,ABS(D8+N8-O8),0),IF((N8-E8-O8)<0,ABS(N8-E8-O8),0)),2) -> 0
A9: 3 | B9: =лютий!B9 -> Мазур Т.В. | C9: 1003 | D9: =лютий!P9 -> 430.5 | E9: =лютий!Q9 -> 0 | F9: =лютий!F9 -> 0 | G9: =лютий!G9 -> 35 | H9: =лютий!H9 -> 0 | I9: =лютий!I9 -> 4.1 | J9: =ROUND(G9*I9,2) -> 143.5 | N9: =ROUND((G9*I9)-K9-L9-M9,2) -> 143.5 | P9: =ROUND(IF(D9=0,IF((N9-E9-O9)>0,(N9-E9-O9),0),IF((D9+N9-O9)>0,(D9+N9-O9),0)),2) -> 574 | Q9: =ROUND(IF(E9=0,IF((D9+N9-O9)<0,ABS(D9+N9-O9),0),IF((N9-E9-O9)<0,ABS(N9-E9-O9),0)),2) -> 0
A10: 4 | B10: =лютий!B10 -> Сокол О.В. | C10: 1004 | D10: =лютий!P10 -> 252.56 | E10: =лютий!Q10 -> 0 | F10: =лютий!F10 -> 0 | G10: =лютий!G10 -> 61.6 | H10: =лютий!H10 -> 0 | I10: =лютий!I10 -> 4.1 | J10: =ROUND(G10*I10,2) -> 252.56 | N10: =ROUND((G10*I10)-K10-L10-M10,2) -> 252.56 | P10: =ROUND(IF(D10=0,IF((N10-E10-O10)>0,(N10-E10-O10),0),IF((D10+N10-O10)>0,(D10+N10-O10),0)),2) -> 505.12 | Q10: =ROUND(IF(E10=0,IF((D10+N10-O10)<0,ABS(D10+N10-O10),0),IF((N10-E10-O10)<0,ABS(N10-E10-O10),0)),2) -> 0
A11: 5 | B11: =лютий!B11 -> Семко Л.І. | C11: 1005 | D11: =лютий!P11 -> 2876.25 | E11: =лютий!Q11 -> 0 | F11: =лютий!F11 -> 0 | G11: =лютий!G11 -> 28.34 | H11: =лютий!H11 -> 0 | I11: =лютий!I11 -> 4.1 | J11: =ROUND(G11*I11,2) -> 116.19 | N11: =ROUND((G11*I11)-K11-L11-M11,2) -> 116.19 | P11: =ROUND(IF(D11=0,IF((N11-E11-O11)>0,(N11-E11-O11),0),IF((D11+N11-O11)>0,(D11+N11-O11),0)),2) -> 2992.44 | Q11: =ROUND(IF(E11=0,IF((D11+N11-O11)<0,ABS(D11+N11-O11),0),IF((N11-E11-O11)<0,ABS(N11-E11-O11),0)),2) -> 0
A12: 5 | B12: =лютий!B12 -> Гаркуша Н.І. | C12: 1005-а | D12: =лютий!P12 -> 1109.88 | E12: =лютий!Q12 -> 0 | F12: =лютий!F12 -> 0 | G12: =лютий!G12 -> 36.66 | H12: =лютий!H12 -> 0 | I12: =лютий!I12 -> 4.1 | J12: =ROUND(G12*I12,2) -> 150.31 | N12: =ROUND((G12*I12)-K12-L12-M12,2) -> 150.31 | P12: =ROUND(IF(D12=0,IF((N12-E12-O12)>0,(N12-E12-O12),0),IF((D12+N12-O12)>0,(D12+N12-O12),0)),2) -> 1260.19 | Q12: =ROUND(IF(E12=0,IF((D12+N12-O12)<0,ABS(D12+N12-O12),0),IF((N12-E12-O12)<0,ABS(N12-E12-O12),0)),2) -> 0
A13: 6 | B13: =лютий!B13 -> Андріяшев В.М | C13: 1006 | D13: =лютий!P13 -> 542.92 | E13: =лютий!Q13 -> 0 | F13: =лютий!F13 -> 0 | G13: =лютий!G13 -> 49.8 | H13: =лютий!H13 -> 0 | I13: =лютий!I13 -> 4.1 | J13: =ROUND(G13*I13,2) -> 204.18 | N13: =ROUND((G13*I13)-K13-L13-M13,2) -> 204.18 | P13: =ROUND(IF(D13=0,IF((N13-E13-O13)>0,(N13-E13-O13),0),IF((D13+N13-O13)>0,(D13+N13-O13),0)),2) -> 747.1 | Q13: =ROUND(IF(E13=0,IF((D13+N13-O13)<0,ABS(D13+N13-O13),0),IF((N13-E13-O13)<0,ABS(N13-E13-O13),0)),2) -> 0
A14: 7 | B14: =лютий!B14 -> Старчикова О.М. | C14: 1007 | D14: =лютий!P14 -> 426.21 | E14: =лютий!Q14 -> 0 | F14: =лютий!F14 -> 0 | G14: =лютий!G14 -> 34.65 | H14: =лютий!H14 -> 0 | I14: =лютий!I14 -> 4.1 | J14: =ROUND(G14*I14,2) -> 142.07 | N14: =ROUND((G14*I14)-K14-L14-M14,2) -> 142.07 | P14: =ROUND(IF(D14=0,IF((N14-E14-O14)>0,(N14-E14-O14),0),IF((D14+N14-O14)>0,(D14+N14-O14),0)),2) -> 568.28 | Q14: =ROUND(IF(E14=0,IF((D14+N14-O14)<0,ABS(D14+N14-O14),0),IF((N14-E14-O14)<0,ABS(N14-E14-O14),0)),2) -> 0
A15: 8 | B15: =лютий!B15 -> Безер Т.М | C15: 1008 | D15: =лютий!P15 -> 502.51 | E15: =лютий!Q15 -> 0 | F15: =лютий!F15 -> 0 | G15: =лютий!G15 -> 62.14 | H15: =лютий!H15 -> 0 | I15: =лютий!I15 -> 4.1 | J15: =ROUND(G15*I15,2) -> 254.77 | N15: =ROUND((G15*I15)-K15-L15-M15,2) -> 254.77 | P15: =ROUND(IF(D15=0,IF((N15-E15-O15)>0,(N15-E15-O15),0),IF((D15+N15-O15)>0,(D15+N15-O15),0)),2) -> 757.28 | Q15: =ROUND(IF(E15=0,IF((D15+N15-O15)<0,ABS(D15+N15-O15),0),IF((N15-E15-O15)<0,ABS(N15-E15-O15),0)),2) -> 0
A16: 9 | B16: =лютий!B16 -> Решетило М.М | C16: 1009 | D16: =лютий!P16 -> 1336.04 | E16: =лютий!Q16 -> 0 | F16: =лютий!F16 -> 0 | G16: =лютий!G16 -> 65.16 | H16: =лютий!H16 -> 0 | I16: =лютий!I16 -> 4.1 | J16: =ROUND(G16*I16,2) -> 267.16 | N16: =ROUND((G16*I16)-K16-L16-M16,2) -> 267.16 | P16: =ROUND(IF(D16=0,IF((N16-E16-O16)>0,(N16-E16-O16),0),IF((D16+N16-O16)>0,(D16+N16-O16),0)),2) -> 1603.2 | Q16: =ROUND(IF(E16=0,IF((D16+N16-O16)<0,ABS(D16+N16-O16),0),IF((N16-E16-O16)<0,ABS(N16-E16-O16),0)),2) -> 0
A17: 10 | B17: =лютий!B17 -> Фесенко О.В. | C17: 1010 | D17: =лютий!P17 -> 5287.51 | E17: =лютий!Q17 -> 0 | F17: =лютий!F17 -> 0 | G17: =лютий!G17 -> 50.1 | H17: =лютий!H17 -> 0 | I17: =лютий!I17 -> 4.1 | J17: =ROUND(G17*I17,2) -> 205.41 | N17: =ROUND((G17*I17)-K17-L17-M17,2) -> 205.41 | P17: =ROUND(IF(D17=0,IF((N17-E17-O17)>0,(N17-E17-O17),0),IF((D17+N17-O17)>0,(D17+N17-O17),0)),2) -> 5492.92 | Q17: =ROUND(IF(E17=0,IF((D17+N17-O17)<0,ABS(D17+N17-O17),0),IF((N17-E17-O17)<0,ABS(N17-E17-O17),0)),2) -> 0
A18: 11 | B18: =лютий!B18 -> Петренко О.М. | C18: 1011 | D18: =лютий!P18 -> 1836.84 | E18: =лютий!Q18 -> 0 | F18: =лютий!F18 -> 0 | G18: =лютий!G18 -> 35.2 | H18: =лютий!H18 -> 0 | I18: =лютий!I18 -> 4.1 | J18: =ROUND(G18*I18,2) -> 144.32 | N18: =ROUND((G18*I18)-K18-L18-M18,2) -> 144.32 | P18: =ROUND(IF(D18=0,IF((N18-E18-O18)>0,(N18-E18-O18),0),IF((D18+N18-O18)>0,(D18+N18-O18),0)),2) -> 1981.16 | Q18: =ROUND(IF(E18=0,IF((D18+N18-O18)<0,ABS(D18+N18-O18),0),IF((N18-E18-O18)<0,ABS(N18-E18-O18),0)),2) -> 0
... A221: 213 | B221: =лютий!B221 -> Корнюшенко О.О. | C221: 60213 | D221: =лютий!P221 -> 8033.2 | E221: =лютий!Q221 -> 0 | F221: =лютий!F221 -> 0 | G221: =лютий!G221 -> 62 | H221: =лютий!H221 -> 0 | I221: =лютий!I221 -> 4.1 | J221: =ROUND(G221*I221,2) -> 254.2 | N221: =ROUND((G221*I221)-K221-L221-M221,2) -> 254.2 | P221: =ROUND(IF(D221=0,IF((N221-E221-O221)>0,(N221-E221-O221),0),IF((D221+N221-O221)>0,(D221+N221-O221),0)),2) -> 8287.4 | Q221: =ROUND(IF(E221=0,IF((D221+N221-O221)<0,ABS(D221+N221-O221),0),IF((N221-E221-O221)<0,ABS(N221-E221-O221),0)),2) -> 0
D222: =SUM(D7:D221) -> 858443.06 | E222: =SUM(E7:E221) -> 3663.19 | G222: =SUM(G7:G221) -> 11652.42 | H222: =SUM(H7:H221) -> 0 | J222: =SUM(J7:J221) -> 47774.99 | K222: =SUM(K7:K221) -> 0 | L222: =SUM(L7:L221) -> 0 | M222: =SUM(M7:M221) -> 0 | N222: =SUM(N7:N221) -> 47774.99 | O222: =SUM(O7:O221) -> 0 | P222: =SUM(P7:P221) -> 905229.57 | Q222: =SUM(Q7:Q221) -> 2674.71
D223: =D222-E222 -> 854779.87 | P223: =P222-Q222 -> 902554.86
U224: 32657.23
U226: =U224-O222 -> 32657.23

Sheet квітень
A1: ОСББ "Карбишева - 22" | N1: 37465042
B2: Відомість нарахувань та оплати мешканців за утримання будинку
B3: у квітні 2026 року
A6: № кв. | B6: ПІБ | C6: Особ. рах. | D6: Д-Т | E6: К-Т | F6: Пільга % | G6: Заг.площа | H6: Пільг. Площа | I6: Тариф | J6: 100% нарах. | K6: Пільгова сума | L6: сплачені суми пільг за реєстрами | M6: Коригування | N6: До сплати | O6: Сплачено | P6: Д-Т | Q6: К-Т
A7: 1 | B7: =березень!B7 -> Бережний В.М. | C7: 1001 | D7: =березень!P7 -> 1613.56 | E7: =березень!Q7 -> 0 | F7: =березень!F7 -> 0 | G7: =березень!G7 -> 64.26 | H7: =березень!H7 -> 0 | I7: =березень!I7 -> 4.1 | J7: =ROUND(G7*I7,2) -> 263.47 | N7: =ROUND((G7*I7)-K7-L7-M7,2) -> 263.47 | P7: =ROUND(IF(D7=0,IF((N7-E7-O7)>0,(N7-E7-O7),0),IF((D7+N7-O7)>0,(D7+N7-O7),0)),2) -> 1877.03 | Q7: =ROUND(IF(E7=0,IF((D7+N7-O7)<0,ABS(D7+N7-O7),0),IF((N7-E7-O7)<0,ABS(N7-E7-O7),0)),2) -> 0
A8: 2 | B8: =березень!B8 -> Старикова Т.О. | C8: 1002 | D8: =березень!P8 -> 599.13 | E8: =березень!Q8 -> 0 | F8: =березень!F8 -> 0 | G8: =березень!G8 -> 48.71 | H8: =березень!H8 -> 0 | I8: =березень!I8 -> 4.1 | J8: =ROUND(G8*I8,2) -> 199.71 | N8: =ROUND((G8*I8)-K8-L8-M8,2) -> 199.71 | P8: =ROUND(IF(D8=0,IF((N8-E8-O8)>0,(N8-E8-O8),0),IF((D8+N8-O8)>0,(D8+N8-O8),0)),2) -> 798.84 | Q8: =ROUND(IF(E8=0,IF((D8+N8-O8)<0,ABS(D8+N8-O8),0),IF((N8-E8-O8)<0,ABS(N8-E8-O8),0)),2) -> 0
A9: 3 | B9: =березень!B9 -> Мазур Т.В. | C9: 1003 | D9: =березень!P9 -> 574 | E9: =березень!Q9 -> 0 | F9: =березень!F9 -> 0 | G9: =березень!G9 -> 35 | H9: =березень!H9 -> 0 | I9: =березень!I9 -> 4.1 | J9: =ROUND(G9*I9,2) -> 143.5 | N9: =ROUND((G9*I9)-K9-L9-M9,2) -> 143.5 | P9: =ROUND(IF(D9=0,IF((N9-E9-O9)>0,(N9-E9-O9),0),IF((D9+N9-O9)>0,(D9+N9-O9),0)),2) -> 717.5 | Q9: =ROUND(IF(E9=0,IF((D9+N9-O9)<0,ABS(D9+N9-O9),0),IF((N9-E9-O9)<0,ABS(N9-E9-O9),0)),2) -> 0
A10: 4 | B10: =березень!B10 -> Сокол О.В. | C10: 1004 | D10: =березень!P10 -> 505.12 | E10: =березень!Q10 -> 0 | F10: =березень!F10 -> 0 | G10: =березень!G10 -> 61.6 | H10: =березень!H10 -> 0 | I10: =березень!I10 -> 4.1 | J10: =ROUND(G10*I10,2) -> 252.56 | N10: =ROUND((G10*I10)-K10-L10-M10,2) -> 252.56 | P10: =ROUND(IF(D10=0,IF((N10-E10-O10)>0,(N10-E10-O10),0),IF((D10+N10-O10)>0,(D10+N10-O10),0)),2) -> 757.68 | Q10: =ROUND(IF(E10=0,IF((D10+N10-O10)<0,ABS(D10+N10-O10),0),IF((N10-E10-O10)<0,ABS(N10-E10-O10),0)),2) -> 0
A11: 5 | B11: =березень!B11 -> Семко Л.І. | C11: 1005 | D11: =березень!P11 -> 2992.44 | E11: =березень!Q11 -> 0 | F11: =березень!F11 -> 0 | G11: =березень!G11 -> 28.34 | H11: =березень!H11 -> 0 | I11: =березень!I11 -> 4.1 | J11: =ROUND(G11*I11,2) -> 116.19 | N11: =ROUND((G11*I11)-K11-L11-M11,2) -> 116.19 | P11: =ROUND(IF(D11=0,IF((N11-E11-O11)>0,(N11-E11-O11),0),IF((D11+N11-O11)>0,(D11+N11-O11),0)),2) -> 3108.63 | Q11: =ROUND(IF(E11=0,IF((D11+N11-O11)<0,ABS(D11+N11-O11),0),IF((N11-E11-O11)<0,ABS(N11-E11-O11),0)),2) -> 0
A12: 5 | B12: =березень!B12 -> Гаркуша Н.І. | C12: 1005-а | D12: =березень!P12 -> 1260.19 | E12: =березень!Q12 -> 0 | F12: =березень!F12 -> 0 | G12: =березень!G12 -> 36.66 | H12: =березень!H12 -> 0 | I12: =березень!I12 -> 4.1 | J12: =ROUND(G12*I12,2) -> 150.31 | N12: =ROUND((G12*I12)-K12-L12-M12,2) -> 150.31 | P12: =ROUND(IF(D12=0,IF((N12-E12-O12)>0,(N12-E12-O12),0),IF((D12+N12-O12)>0,(D12+N12-O12),0)),2) -> 1410.5 | Q12: =ROUND(IF(E12=0,IF((D12+N12-O12)<0,ABS(D12+N12-O12),0),IF((N12-E12-O12)<0,ABS(N12-E12-O12),0)),2) -> 0
A13: 6 | B13: =березень!B13 -> Андріяшев В.М | C13: 1006 | D13: =березень!P13 -> 747.1 | E13: =березень!Q13 -> 0 | F13: =березень!F13 -> 0 | G13: =березень!G13 -> 49.8 | H13: =березень!H13 -> 0 | I13: =березень!I13 -> 4.1 | J13: =ROUND(G13*I13,2) -> 204.18 | N13: =ROUND((G13*I13)-K13-L13-M13,2) -> 204.18 | P13: =ROUND(IF(D13=0,IF((N13-E13-O13)>0,(N13-E13-O13),0),IF((D13+N13-O13)>0,(D13+N13-O13),0)),2) -> 951.28 | Q13: =ROUND(IF(E13=0,IF((D13+N13-O13)<0,ABS(D13+N13-O13),0),IF((N13-E13-O13)<0,ABS(N13-E13-O13),0)),2) -> 0
A14: 7 | B14: =березень!B14 -> Старчикова О.М. | C14: 1007 | D14: =березень!P14 -> 568.28 | E14: =березень!Q14 -> 0 | F14: =березень!F14 -> 0 | G14: =березень!G14 -> 34.65 | H14: =березень!H14 -> 0 | I14: =березень!I14 -> 4.1 | J14: =ROUND(G14*I14,2) -> 142.07 | N14: =ROUND((G14*I14)-K14-L14-M14,2) -> 142.07 | P14: =ROUND(IF(D14=0,IF((N14-E14-O14)>0,(N14-E14-O14),0),IF((D14+N14-O14)>0,(D14+N14-O14),0)),2) -> 710.35 | Q14: =ROUND(IF(E14=0,IF((D14+N14-O14)<0,ABS(D14+N14-O14),0),IF((N14-E14-O14)<0,ABS(N14-E14-O14),0)),2) -> 0
A15: 8 | B15: =березень!B15 -> Безер Т.М | C15: 1008 | D15: =березень!P15 -> 757.28 | E15: =березень!Q15 -> 0 | F15: =березень!F15 -> 0 | G15: =березень!G15 -> 62.14 | H15: =березень!H15 -> 0 | I15: =березень!I15 -> 4.1 | J15: =ROUND(G15*I15,2) -> 254.77 | N15: =ROUND((G15*I15)-K15-L15-M15,2) -> 254.77 | P15: =ROUND(IF(D15=0,IF((N15-E15-O15)>0,(N15-E15-O15),0),IF((D15+N15-O15)>0,(D15+N15-O15),0)),2) -> 1012.05 | Q15: =ROUND(IF(E15=0,IF((D15+N15-O15)<0,ABS(D15+N15-O15),0),IF((N15-E15-O15)<0,ABS(N15-E15-O15),0)),2) -> 0
A16: 9 | B16: =березень!B16 -> Решетило М.М | C16: 1009 | D16: =березень!P16 -> 1603.2 | E16: =березень!Q16 -> 0 | F16: =березень!F16 -> 0 | G16: =березень!G16 -> 65.16 | H16: =березень!H16 -> 0 | I16: =березень!I16 -> 4.1 | J16: =ROUND(G16*I16,2) -> 267.16 | N16: =ROUND((G16*I16)-K16-L16-M16,2) -> 267.16 | P16: =ROUND(IF(D16=0,IF((N16-E16-O16)>0,(N16-E16-O16),0),IF((D16+N16-O16)>0,(D16+N16-O16),0)),2) -> 1870.36 | Q16: =ROUND(IF(E16=0,IF((D16+N16-O16)<0,ABS(D16+N16-O16),0),IF((N16-E16-O16)<0,ABS(N16-E16-O16),0)),2) -> 0
A17: 10 | B17: =березень!B17 -> Фесенко О.В. | C17: 1010 | D17: =березень!P17 -> 5492.92 | E17: =березень!Q17 -> 0 | F17: =березень!F17 -> 0 | G17: =березень!G17 -> 50.1 | H17: =березень!H17 -> 0 | I17: =березень!I17 -> 4.1 | J17: =ROUND(G17*I17,2) -> 205.41 | N17: =ROUND((G17*I17)-K17-L17-M17,2) -> 205.41 | P17: =ROUND(IF(D17=0,IF((N17-E17-O17)>0,(N17-E17-O17),0),IF((D17+N17-O17)>0,(D17+N17-O17),0)),2) -> 5698.33 | Q17: =ROUND(IF(E17=0,IF((D17+N17-O17)<0,ABS(D17+N17-O17),0),IF((N17-E17-O17)<0,ABS(N17-E17-O17),0)),2) -> 0
A18: 11 | B18: =березень!B18 -> Петренко О.М. | C18: 1011 | D18: =березень!P18 -> 1981.16 | E18: =березень!Q18 -> 0 | F18: =березень!F18 -> 0 | G18: =березень!G18 -> 35.2 | H18: =березень!H18 -> 0 | I18: =березень!I18 -> 4.1 | J18: =ROUND(G18*I18,2) -> 144.32 | N18: =ROUND((G18*I18)-K18-L18-M18,2) -> 144.32 | P18: =ROUND(IF(D18=0,IF((N18-E18-O18)>0,(N18-E18-O18),0),IF((D18+N18-O18)>0,(D18+N18-O18),0)),2) -> 2125.48 | Q18: =ROUND(IF(E18=0,IF((D18+N18-O18)<0,ABS(D18+N18-O18),0),IF((N18-E18-O18)<0,ABS(N18-E18-O18),0)),2) -> 0
... A221: 213 | B221: =березень!B221 -> Корнюшенко О.О. | C221: 60213 | D221: =березень!P221 -> 8287.4 | E221: =березень!Q221 -> 0 | F221: =березень!F221 -> 0 | G221: =березень!G221 -> 62 | H221: =березень!H221 -> 0 | I221: =березень!I221 -> 4.1 | J221: =ROUND(G221*I221,2) -> 254.2 | N221: =ROUND((G221*I221)-K221-L221-M221,2) -> 254.2 | P221: =ROUND(IF(D221=0,IF((N221-E221-O221)>0,(N221-E221-O221),0),IF((D221+N221-O221)>0,(D221+N221-O221),0)),2) -> 8541.6 | Q221: =ROUND(IF(E221=0,IF((D221+N221-O221)<0,ABS(D221+N221-O221),0),IF((N221-E221-O221)<0,ABS(N221-E221-O221),0)),2) -> 0
D222: =SUM(D7:D221) -> 905229.57 | E222: =SUM(E7:E221) -> 2674.71 | G222: =SUM(G7:G221) -> 11652.42 | H222: =SUM(H7:H221) -> 0 | J222: =SUM(J7:J221) -> 47774.99 | K222: =SUM(K7:K221) -> 0 | L222: =SUM(L7:L221) -> 0 | M222: =SUM(M7:M221) -> 0 | N222: =SUM(N7:N221) -> 47774.99 | O222: =SUM(O7:O221) -> 0 | P222: =SUM(P7:P221) -> 952455.69 | Q222: =SUM(Q7:Q221) -> 2125.84
D223: =D222-E222 -> 902554.86 | P223: =P222-Q222 -> 950329.85
V224: 29813.5
V225: =O222-V224 -> -29813.5

Sheet травень
A1: ОСББ "Карбишева - 22" | N1: 37465042
B2: Відомість нарахувань та оплати мешканців за утримання будинку
B3: у травні 2026 року
A6: № кв. | B6: ПІБ | C6: Особ. рах. | D6: Д-Т | E6: К-Т | F6: Пільга % | G6: Заг.площа | H6: Пільг. Площа | I6: Тариф | J6: 100% нарах. | K6: Пільгова сума | L6: сплачені суми пільг за реєстрами | M6: Коригування | N6: До сплати | O6: Сплачено | P6: Д-Т | Q6: К-Т
A7: 1 | B7: =квітень!B7 -> Бережний В.М. | C7: 1001 | D7: =квітень!P7 -> 1877.03 | E7: =квітень!Q7 -> 0 | F7: =квітень!F7 -> 0 | G7: =квітень!G7 -> 64.26 | H7: =квітень!H7 -> 0 | I7: =квітень!I7 -> 4.1 | J7: =ROUND(G7*I7,2) -> 263.47 | N7: =ROUND((G7*I7)-K7-L7-M7,2) -> 263.47 | P7: =ROUND(IF(D7=0,IF((N7-E7-O7)>0,(N7-E7-O7),0),IF((D7+N7-O7)>0,(D7+N7-O7),0)),2) -> 2140.5 | Q7: =ROUND(IF(E7=0,IF((D7+N7-O7)<0,ABS(D7+N7-O7),0),IF((N7-E7-O7)<0,ABS(N7-E7-O7),0)),2) -> 0
A8: 2 | B8: =квітень!B8 -> Старикова Т.О. | C8: 1002 | D8: =квітень!P8 -> 798.84 | E8: =квітень!Q8 -> 0 | F8: =квітень!F8 -> 0 | G8: =квітень!G8 -> 48.71 | H8: =квітень!H8 -> 0 | I8: =квітень!I8 -> 4.1 | J8: =ROUND(G8*I8,2) -> 199.71 | N8: =ROUND((G8*I8)-K8-L8-M8,2) -> 199.71 | P8: =ROUND(IF(D8=0,IF((N8-E8-O8)>0,(N8-E8-O8),0),IF((D8+N8-O8)>0,(D8+N8-O8),0)),2) -> 998.55 | Q8: =ROUND(IF(E8=0,IF((D8+N8-O8)<0,ABS(D8+N8-O8),0),IF((N8-E8-O8)<0,ABS(N8-E8-O8),0)),2) -> 0
A9: 3 | B9: =квітень!B9 -> Мазур Т.В. | C9: 1003 | D9: =квітень!P9 -> 717.5 | E9: =квітень!Q9 -> 0 | F9: =квітень!F9 -> 0 | G9: =квітень!G9 -> 35 | H9: =квітень!H9 -> 0 | I9: =квітень!I9 -> 4.1 | J9: =ROUND(G9*I9,2) -> 143.5 | N9: =ROUND((G9*I9)-K9-L9-M9,2) -> 143.5 | P9: =ROUND(IF(D9=0,IF((N9-E9-O9)>0,(N9-E9-O9),0),IF((D9+N9-O9)>0,(D9+N9-O9),0)),2) -> 861 | Q9: =ROUND(IF(E9=0,IF((D9+N9-O9)<0,ABS(D9+N9-O9),0),IF((N9-E9-O9)<0,ABS(N9-E9-O9),0)),2) -> 0
A10: 4 | B10: =квітень!B10 -> Сокол О.В. | C10: 1004 | D10: =квітень!P10 -> 757.68 | E10: =квітень!Q10 -> 0 | F10: =квітень!F10 -> 0 | G10: =квітень!G10 -> 61.6 | H10: =квітень!H10 -> 0 | I10: =квітень!I10 -> 4.1 | J10: =ROUND(G10*I10,2) -> 252.56 | N10: =ROUND((G10*I10)-K10-L10-M10,2) -> 252.56 | P10: =ROUND(IF(D10=0,IF((N10-E10-O10)>0,(N10-E10-O10),0),IF((D10+N10-O10)>0,(D10+N10-O10),0)),2) -> 1010.24 | Q10: =ROUND(IF(E10=0,IF((D10+N10-O10)<0,ABS(D10+N10-O10),0),IF((N10-E10-O10)<0,ABS(N10-E10-O10),0)),2) -> 0
A11: 5 | B11: =квітень!B11 -> Семко Л.І. | C11: 1005 | D11: =квітень!P11 -> 3108.63 | E11: =квітень!Q11 -> 0 | F11: =квітень!F11 -> 0 | G11: =квітень!G11 -> 28.34 | H11: =квітень!H11 -> 0 | I11: =квітень!I11 -> 4.1 | J11: =ROUND(G11*I11,2) -> 116.19 | N11: =ROUND((G11*I11)-K11-L11-M11,2) -> 116.19 | P11: =ROUND(IF(D11=0,IF((N11-E11-O11)>0,(N11-E11-O11),0),IF((D11+N11-O11)>0,(D11+N11-O11),0)),2) -> 3224.82 | Q11: =ROUND(IF(E11=0,IF((D11+N11-O11)<0,ABS(D11+N11-O11),0),IF((N11-E11-O11)<0,ABS(N11-E11-O11),0)),2) -> 0
A12: 5 | B12: =квітень!B12 -> Гаркуша Н.І. | C12: 1005-а | D12: =квітень!P12 -> 1410.5 | E12: =квітень!Q12 -> 0 | F12: =квітень!F12 -> 0 | G12: =квітень!G12 -> 36.66 | H12: =квітень!H12 -> 0 | I12: =квітень!I12 -> 4.1 | J12: =ROUND(G12*I12,2) -> 150.31 | N12: =ROUND((G12*I12)-K12-L12-M12,2) -> 150.31 | P12: =ROUND(IF(D12=0,IF((N12-E12-O12)>0,(N12-E12-O12),0),IF((D12+N12-O12)>0,(D12+N12-O12),0)),2) -> 1560.81 | Q12: =ROUND(IF(E12=0,IF((D12+N12-O12)<0,ABS(D12+N12-O12),0),IF((N12-E12-O12)<0,ABS(N12-E12-O12),0)),2) -> 0
A13: 6 | B13: =квітень!B13 -> Андріяшев В.М | C13: 1006 | D13: =квітень!P13 -> 951.28 | E13: =квітень!Q13 -> 0 | F13: =квітень!F13 -> 0 | G13: =квітень!G13 -> 49.8 | H13: =квітень!H13 -> 0 | I13: =квітень!I13 -> 4.1 | J13: =ROUND(G13*I13,2) -> 204.18 | N13: =ROUND((G13*I13)-K13-L13-M13,2) -> 204.18 | P13: =ROUND(IF(D13=0,IF((N13-E13-O13)>0,(N13-E13-O13),0),IF((D13+N13-O13)>0,(D13+N13-O13),0)),2) -> 1155.46 | Q13: =ROUND(IF(E13=0,IF((D13+N13-O13)<0,ABS(D13+N13-O13),0),IF((N13-E13-O13)<0,ABS(N13-E13-O13),0)),2) -> 0
A14: 7 | B14: =квітень!B14 -> Старчикова О.М. | C14: 1007 | D14: =квітень!P14 -> 710.35 | E14: =квітень!Q14 -> 0 | F14: =квітень!F14 -> 0 | G14: =квітень!G14 -> 34.65 | H14: =квітень!H14 -> 0 | I14: =квітень!I14 -> 4.1 | J14: =ROUND(G14*I14,2) -> 142.07 | N14: =ROUND((G14*I14)-K14-L14-M14,2) -> 142.07 | P14: =ROUND(IF(D14=0,IF((N14-E14-O14)>0,(N14-E14-O14),0),IF((D14+N14-O14)>0,(D14+N14-O14),0)),2) -> 852.42 | Q14: =ROUND(IF(E14=0,IF((D14+N14-O14)<0,ABS(D14+N14-O14),0),IF((N14-E14-O14)<0,ABS(N14-E14-O14),0)),2) -> 0
A15: 8 | B15: =квітень!B15 -> Безер Т.М | C15: 1008 | D15: =квітень!P15 -> 1012.05 | E15: =квітень!Q15 -> 0 | F15: =квітень!F15 -> 0 | G15: =квітень!G15 -> 62.14 | H15: =квітень!H15 -> 0 | I15: =квітень!I15 -> 4.1 | J15: =ROUND(G15*I15,2) -> 254.77 | N15: =ROUND((G15*I15)-K15-L15-M15,2) -> 254.77 | P15: =ROUND(IF(D15=0,IF((N15-E15-O15)>0,(N15-E15-O15),0),IF((D15+N15-O15)>0,(D15+N15-O15),0)),2) -> 1266.82 | Q15: =ROUND(IF(E15=0,IF((D15+N15-O15)<0,ABS(D15+N15-O15),0),IF((N15-E15-O15)<0,ABS(N15-E15-O15),0)),2) -> 0
A16: 9 | B16: =квітень!B16 -> Решетило М.М | C16: 1009 | D16: =квітень!P16 -> 1870.36 | E16: =квітень!Q16 -> 0 | F16: =квітень!F16 -> 0 | G16: =квітень!G16 -> 65.16 | H16: =квітень!H16 -> 0 | I16: =квітень!I16 -> 4.1 | J16: =ROUND(G16*I16,2) -> 267.16 | N16: =ROUND((G16*I16)-K16-L16-M16,2) -> 267.16 | P16: =ROUND(IF(D16=0,IF((N16-E16-O16)>0,(N16-E16-O16),0),IF((D16+N16-O16)>0,(D16+N16-O16),0)),2) -> 2137.52 | Q16: =ROUND(IF(E16=0,IF((D16+N16-O16)<0,ABS(D16+N16-O16),0),IF((N16-E16-O16)<0,ABS(N16-E16-O16),0)),2) -> 0
A17: 10 | B17: =квітень!B17 -> Фесенко О.В. | C17: 1010 | D17: =квітень!P17 -> 5698.33 | E17: =квітень!Q17 -> 0 | F17: =квітень!F17 -> 0 | G17: =квітень!G17 -> 50.1 | H17: =квітень!H17 -> 0 | I17: =квітень!I17 -> 4.1 | J17: =ROUND(G17*I17,2) -> 205.41 | N17: =ROUND((G17*I17)-K17-L17-M17,2) -> 205.41 | P17: =ROUND(IF(D17=0,IF((N17-E17-O17)>0,(N17-E17-O17),0),IF((D17+N17-O17)>0,(D17+N17-O17),0)),2) -> 5903.74 | Q17: =ROUND(IF(E17=0,IF((D17+N17-O17)<0,ABS(D17+N17-O17),0),IF((N17-E17-O17)<0,ABS(N17-E17-O17),0)),2) -> 0
A18: 11 | B18: =квітень!B18 -> Петренко О.М. | C18: 1011 | D18: =квітень!P18 -> 2125.48 | E18: =квітень!Q18 -> 0 | F18: =квітень!F18 -> 0 | G18: =квітень!G18 -> 35.2 | H18: =квітень!H18 -> 0 | I18: =квітень!I18 -> 4.1 | J18: =ROUND(G18*I18,2) -> 144.32 | N18: =ROUND((G18*I18)-K18-L18-M18,2) -> 144.32 | P18: =ROUND(IF(D18=0,IF((N18-E18-O18)>0,(N18-E18-O18),0),IF((D18+N18-O18)>0,(D18+N18-O18),0)),2) -> 2269.8 | Q18: =ROUND(IF(E18=0,IF((D18+N18-O18)<0,ABS(D18+N18-O18),0),IF((N18-E18-O18)<0,ABS(N18-E18-O18),0)),2) -> 0
... A221: 213 | B221: =квітень!B221 -> Корнюшенко О.О. | C221: 60213 | D221: =квітень!P221 -> 8541.6 | E221: =квітень!Q221 -> 0 | F221: =квітень!F221 -> 0 | G221: =квітень!G221 -> 62 | H221: =квітень!H221 -> 0 | I221: =квітень!I221 -> 4.1 | J221: =ROUND(G221*I221,2) -> 254.2 | N221: =ROUND((G221*I221)-K221-L221-M221,2) -> 254.2 | P221: =ROUND(IF(D221=0,IF((N221-E221-O221)>0,(N221-E221-O221),0),IF((D221+N221-O221)>0,(D221+N221-O221),0)),2) -> 8795.8 | Q221: =ROUND(IF(E221=0,IF((D221+N221-O221)<0,ABS(D221+N221-O221),0),IF((N221-E221-O221)<0,ABS(N221-E221-O221),0)),2) -> 0
D222: =SUM(D7:D221) -> 952455.69 | E222: =SUM(E7:E221) -> 2125.84 | G222: =SUM(G7:G221) -> 11652.42 | H222: =SUM(H7:H221) -> 0 | J222: =SUM(J7:J221) -> 47774.99 | K222: =SUM(K7:K221) -> 0 | L222: =SUM(L7:L221) -> 0 | M222: =SUM(M7:M221) -> 0 | N222: =SUM(N7:N221) -> 47774.99 | O222: =SUM(O7:O221) -> 0 | P222: =SUM(P7:P221) -> 999822.32 | Q222: =SUM(Q7:Q221) -> 1717.48
D223: =D222-E222 -> 950329.85 | P223: =P222-Q222 -> 998104.84
V224: =O222-U225 -> -39575.71
U225: 39575.71
U226: =U225-O222 -> 39575.71

Sheet червень
A1: ОСББ "Карбишева - 22" | N1: 37465042
B2: Відомість нарахувань та оплати мешканців за утримання будинку
B3: у червні 2025 року
A6: № кв. | B6: ПІБ | C6: Особ. рах. | D6: Д-Т | E6: К-Т | F6: Пільга % | G6: Заг.площа | H6: Пільг. Площа | I6: Тариф | J6: 100% нарах. | K6: Пільгова сума | L6: сплачені суми пільг за реєстрами | M6: Коригування | N6: До сплати | O6: Сплачено | P6: Д-Т | Q6: К-Т
A7: 1 | B7: Бережний В.М. | C7: 1001 | D7: =травень!P7 -> 2140.5 | E7: =травень!Q7 -> 0 | F7: =травень!F7 -> 0 | G7: =травень!G7 -> 64.26 | H7: =травень!H7 -> 0 | I7: =травень!I7 -> 4.1 | J7: =ROUND(G7*I7,2) -> 263.47 | N7: =ROUND((G7*I7)-K7-L7-M7,2) -> 263.47 | P7: =ROUND(IF(D7=0,IF((N7-E7-O7)>0,(N7-E7-O7),0),IF((D7+N7-O7)>0,(D7+N7-O7),0)),2) -> 2403.97 | Q7: =ROUND(IF(E7=0,IF((D7+N7-O7)<0,ABS(D7+N7-O7),0),IF((N7-E7-O7)<0,ABS(N7-E7-O7),0)),2) -> 0
A8: 2 | B8: Старикова Т.О. | C8: 1002 | D8: =травень!P8 -> 998.55 | E8: =травень!Q8 -> 0 | F8: =травень!F8 -> 0 | G8: =травень!G8 -> 48.71 | H8: =травень!H8 -> 0 | I8: =травень!I8 -> 4.1 | J8: =ROUND(G8*I8,2) -> 199.71 | N8: =ROUND((G8*I8)-K8-L8-M8,2) -> 199.71 | P8: =ROUND(IF(D8=0,IF((N8-E8-O8)>0,(N8-E8-O8),0),IF((D8+N8-O8)>0,(D8+N8-O8),0)),2) -> 1198.26 | Q8: =ROUND(IF(E8=0,IF((D8+N8-O8)<0,ABS(D8+N8-O8),0),IF((N8-E8-O8)<0,ABS(N8-E8-O8),0)),2) -> 0
A9: 3 | B9: Мазур Т.В. | C9: 1003 | D9: =травень!P9 -> 861 | E9: =травень!Q9 -> 0 | F9: =травень!F9 -> 0 | G9: =травень!G9 -> 35 | H9: =травень!H9 -> 0 | I9: =травень!I9 -> 4.1 | J9: =ROUND(G9*I9,2) -> 143.5 | N9: =ROUND((G9*I9)-K9-L9-M9,2) -> 143.5 | P9: =ROUND(IF(D9=0,IF((N9-E9-O9)>0,(N9-E9-O9),0),IF((D9+N9-O9)>0,(D9+N9-O9),0)),2) -> 1004.5 | Q9: =ROUND(IF(E9=0,IF((D9+N9-O9)<0,ABS(D9+N9-O9),0),IF((N9-E9-O9)<0,ABS(N9-E9-O9),0)),2) -> 0
A10: 4 | B10: Сокол О.В. | C10: 1004 | D10: =травень!P10 -> 1010.24 | E10: =травень!Q10 -> 0 | F10: =травень!F10 -> 0 | G10: =травень!G10 -> 61.6 | H10: =травень!H10 -> 0 | I10: =травень!I10 -> 4.1 | J10: =ROUND(G10*I10,2) -> 252.56 | N10: =ROUND((G10*I10)-K10-L10-M10,2) -> 252.56 | P10: =ROUND(IF(D10=0,IF((N10-E10-O10)>0,(N10-E10-O10),0),IF((D10+N10-O10)>0,(D10+N10-O10),0)),2) -> 1262.8 | Q10: =ROUND(IF(E10=0,IF((D10+N10-O10)<0,ABS(D10+N10-O10),0),IF((N10-E10-O10)<0,ABS(N10-E10-O10),0)),2) -> 0
A11: 5 | B11: Семко Л.І. | C11: 1005 | D11: =травень!P11 -> 3224.82 | E11: =травень!Q11 -> 0 | F11: =травень!F11 -> 0 | G11: =травень!G11 -> 28.34 | H11: =травень!H11 -> 0 | I11: =травень!I11 -> 4.1 | J11: =ROUND(G11*I11,2) -> 116.19 | N11: =ROUND((G11*I11)-K11-L11-M11,2) -> 116.19 | P11: =ROUND(IF(D11=0,IF((N11-E11-O11)>0,(N11-E11-O11),0),IF((D11+N11-O11)>0,(D11+N11-O11),0)),2) -> 3341.01 | Q11: =ROUND(IF(E11=0,IF((D11+N11-O11)<0,ABS(D11+N11-O11),0),IF((N11-E11-O11)<0,ABS(N11-E11-O11),0)),2) -> 0
A12: 5 | B12: Гаркуша Н.І. | C12: 1005-а | D12: =травень!P12 -> 1560.81 | E12: =травень!Q12 -> 0 | F12: =травень!F12 -> 0 | G12: =травень!G12 -> 36.66 | H12: =травень!H12 -> 0 | I12: =травень!I12 -> 4.1 | J12: =ROUND(G12*I12,2) -> 150.31 | N12: =ROUND((G12*I12)-K12-L12-M12,2) -> 150.31 | P12: =ROUND(IF(D12=0,IF((N12-E12-O12)>0,(N12-E12-O12),0),IF((D12+N12-O12)>0,(D12+N12-O12),0)),2) -> 1711.12 | Q12: =ROUND(IF(E12=0,IF((D12+N12-O12)<0,ABS(D12+N12-O12),0),IF((N12-E12-O12)<0,ABS(N12-E12-O12),0)),2) -> 0
A13: 6 | B13: Андріяшев В.М | C13: 1006 | D13: =травень!P13 -> 1155.46 | E13: =травень!Q13 -> 0 | F13: =травень!F13 -> 0 | G13: =травень!G13 -> 49.8 | H13: =травень!H13 -> 0 | I13: =травень!I13 -> 4.1 | J13: =ROUND(G13*I13,2) -> 204.18 | N13: =ROUND((G13*I13)-K13-L13-M13,2) -> 204.18 | P13: =ROUND(IF(D13=0,IF((N13-E13-O13)>0,(N13-E13-O13),0),IF((D13+N13-O13)>0,(D13+N13-O13),0)),2) -> 1359.64 | Q13: =ROUND(IF(E13=0,IF((D13+N13-O13)<0,ABS(D13+N13-O13),0),IF((N13-E13-O13)<0,ABS(N13-E13-O13),0)),2) -> 0
A14: 7 | B14: Старчикова О.М. | C14: 1007 | D14: =травень!P14 -> 852.42 | E14: =травень!Q14 -> 0 | F14: =травень!F14 -> 0 | G14: =травень!G14 -> 34.65 | H14: =травень!H14 -> 0 | I14: =травень!I14 -> 4.1 | J14: =ROUND(G14*I14,2) -> 142.07 | N14: =ROUND((G14*I14)-K14-L14-M14,2) -> 142.07 | P14: =ROUND(IF(D14=0,IF((N14-E14-O14)>0,(N14-E14-O14),0),IF((D14+N14-O14)>0,(D14+N14-O14),0)),2) -> 994.49 | Q14: =ROUND(IF(E14=0,IF((D14+N14-O14)<0,ABS(D14+N14-O14),0),IF((N14-E14-O14)<0,ABS(N14-E14-O14),0)),2) -> 0
A15: 8 | B15: Безер Т.М | C15: 1008 | D15: =травень!P15 -> 1266.82 | E15: =травень!Q15 -> 0 | F15: =травень!F15 -> 0 | G15: =травень!G15 -> 62.14 | H15: =травень!H15 -> 0 | I15: =травень!I15 -> 4.1 | J15: =ROUND(G15*I15,2) -> 254.77 | N15: =ROUND((G15*I15)-K15-L15-M15,2) -> 254.77 | P15: =ROUND(IF(D15=0,IF((N15-E15-O15)>0,(N15-E15-O15),0),IF((D15+N15-O15)>0,(D15+N15-O15),0)),2) -> 1521.59 | Q15: =ROUND(IF(E15=0,IF((D15+N15-O15)<0,ABS(D15+N15-O15),0),IF((N15-E15-O15)<0,ABS(N15-E15-O15),0)),2) -> 0
A16: 9 | B16: Решетило М.М | C16: 1009 | D16: =травень!P16 -> 2137.52 | E16: =травень!Q16 -> 0 | F16: =травень!F16 -> 0 | G16: =травень!G16 -> 65.16 | H16: =травень!H16 -> 0 | I16: =травень!I16 -> 4.1 | J16: =ROUND(G16*I16,2) -> 267.16 | N16: =ROUND((G16*I16)-K16-L16-M16,2) -> 267.16 | P16: =ROUND(IF(D16=0,IF((N16-E16-O16)>0,(N16-E16-O16),0),IF((D16+N16-O16)>0,(D16+N16-O16),0)),2) -> 2404.68 | Q16: =ROUND(IF(E16=0,IF((D16+N16-O16)<0,ABS(D16+N16-O16),0),IF((N16-E16-O16)<0,ABS(N16-E16-O16),0)),2) -> 0
A17: 10 | B17: Фесенко О.В. | C17: 1010 | D17: =травень!P17 -> 5903.74 | E17: =травень!Q17 -> 0 | F17: =травень!F17 -> 0 | G17: =травень!G17 -> 50.1 | H17: =травень!H17 -> 0 | I17: =травень!I17 -> 4.1 | J17: =ROUND(G17*I17,2) -> 205.41 | N17: =ROUND((G17*I17)-K17-L17-M17,2) -> 205.41 | P17: =ROUND(IF(D17=0,IF((N17-E17-O17)>0,(N17-E17-O17),0),IF((D17+N17-O17)>0,(D17+N17-O17),0)),2) -> 6109.15 | Q17: =ROUND(IF(E17=0,IF((D17+N17-O17)<0,ABS(D17+N17-O17),0),IF((N17-E17-O17)<0,ABS(N17-E17-O17),0)),2) -> 0
A18: 11 | B18: Петренко О.М. | C18: 1011 | D18: =травень!P18 -> 2269.8 | E18: =травень!Q18 -> 0 | F18: =травень!F18 -> 0 | G18: =травень!G18 -> 35.2 | H18: =травень!H18 -> 0 | I18: =травень!I18 -> 4.1 | J18: =ROUND(G18*I18,2) -> 144.32 | N18: =ROUND((G18*I18)-K18-L18-M18,2) -> 144.32 | P18: =ROUND(IF(D18=0,IF((N18-E18-O18)>0,(N18-E18-O18),0),IF((D18+N18-O18)>0,(D18+N18-O18),0)),2) -> 2414.12 | Q18: =ROUND(IF(E18=0,IF((D18+N18-O18)<0,ABS(D18+N18-O18),0),IF((N18-E18-O18)<0,ABS(N18-E18-O18),0)),2) -> 0
... A221: 213 | B221: Корнюшенко О.О. | C221: 60213 | D221: =травень!P221 -> 8795.8 | E221: =травень!Q221 -> 0 | F221: =травень!F221 -> 0 | G221: =травень!G221 -> 62 | H221: =травень!H221 -> 0 | I221: =травень!I221 -> 4.1 | J221: =ROUND(G221*I221,2) -> 254.2 | N221: =ROUND((G221*I221)-K221-L221-M221,2) -> 254.2 | P221: =ROUND(IF(D221=0,IF((N221-E221-O221)>0,(N221-E221-O221),0),IF((D221+N221-O221)>0,(D221+N221-O221),0)),2) -> 9050 | Q221: =ROUND(IF(E221=0,IF((D221+N221-O221)<0,ABS(D221+N221-O221),0),IF((N221-E221-O221)<0,ABS(N221-E221-O221),0)),2) -> 0
D222: =SUM(D7:D221) -> 999822.32 | E222: =SUM(E7:E221) -> 1717.48 | G222: =SUM(G7:G221) -> 11652.42 | H222: =SUM(H7:H221) -> 0 | J222: =SUM(J7:J221) -> 47774.99 | K222: =SUM(K7:K221) -> 0 | L222: =SUM(L7:L221) -> 0 | M222: =SUM(M7:M221) -> 0 | N222: =SUM(N7:N221) -> 47774.99 | O222: =SUM(O7:O221) -> 0 | P222: =SUM(P7:P221) -> 1047188.9 | Q222: =SUM(Q7:Q221) -> 1309.12
D223: =D222-E222 -> 998104.84 | P223: =P222-Q222 -> 1045879.8 | U223: 43627.1
U224: =U223-O222 -> 43627.1

Sheet липень
A1: ОСББ "Карбишева - 22" | N1: 37465042
B2: Відомість нарахувань та оплати мешканців за утримання будинку
B3: у липні 2026 року
A6: № кв. | B6: ПІБ | C6: Особ. рах. | D6: Д-Т | E6: К-Т | F6: Пільга % | G6: Заг.площа | H6: Пільг. Площа | I6: Тариф | J6: 100% нарах. | K6: Пільгова сума | L6: сплачені суми пільг за реєстрами | M6: Коригування | N6: До сплати | O6: Сплачено | P6: Д-Т | Q6: К-Т
A7: 1 | B7: =червень!B7 -> Бережний В.М. | C7: 1001 | D7: =червень!P7 -> 2403.97 | E7: =червень!Q7 -> 0 | F7: =червень!F7 -> 0 | G7: =червень!G7 -> 64.26 | H7: =червень!H7 -> 0 | I7: =червень!I7 -> 4.1 | J7: =ROUND(G7*I7,2) -> 263.47 | N7: =ROUND((G7*I7)-K7-L7-M7,2) -> 263.47 | P7: =ROUND(IF(D7=0,IF((N7-E7-O7)>0,(N7-E7-O7),0),IF((D7+N7-O7)>0,(D7+N7-O7),0)),2) -> 2667.44 | Q7: =ROUND(IF(E7=0,IF((D7+N7-O7)<0,ABS(D7+N7-O7),0),IF((N7-E7-O7)<0,ABS(N7-E7-O7),0)),2) -> 0
A8: 2 | B8: =червень!B8 -> Старикова Т.О. | C8: 1002 | D8: =червень!P8 -> 1198.26 | E8: =червень!Q8 -> 0 | F8: =червень!F8 -> 0 | G8: =червень!G8 -> 48.71 | H8: =червень!H8 -> 0 | I8: =червень!I8 -> 4.1 | J8: =ROUND(G8*I8,2) -> 199.71 | N8: =ROUND((G8*I8)-K8-L8-M8,2) -> 199.71 | P8: =ROUND(IF(D8=0,IF((N8-E8-O8)>0,(N8-E8-O8),0),IF((D8+N8-O8)>0,(D8+N8-O8),0)),2) -> 1397.97 | Q8: =ROUND(IF(E8=0,IF((D8+N8-O8)<0,ABS(D8+N8-O8),0),IF((N8-E8-O8)<0,ABS(N8-E8-O8),0)),2) -> 0
A9: 3 | B9: =червень!B9 -> Мазур Т.В. | C9: 1003 | D9: =червень!P9 -> 1004.5 | E9: =червень!Q9 -> 0 | F9: =червень!F9 -> 0 | G9: =червень!G9 -> 35 | H9: =червень!H9 -> 0 | I9: =червень!I9 -> 4.1 | J9: =ROUND(G9*I9,2) -> 143.5 | N9: =ROUND((G9*I9)-K9-L9-M9,2) -> 143.5 | P9: =ROUND(IF(D9=0,IF((N9-E9-O9)>0,(N9-E9-O9),0),IF((D9+N9-O9)>0,(D9+N9-O9),0)),2) -> 1148 | Q9: =ROUND(IF(E9=0,IF((D9+N9-O9)<0,ABS(D9+N9-O9),0),IF((N9-E9-O9)<0,ABS(N9-E9-O9),0)),2) -> 0
A10: 4 | B10: =червень!B10 -> Сокол О.В. | C10: 1004 | D10: =червень!P10 -> 1262.8 | E10: =червень!Q10 -> 0 | F10: =червень!F10 -> 0 | G10: =червень!G10 -> 61.6 | H10: =червень!H10 -> 0 | I10: =червень!I10 -> 4.1 | J10: =ROUND(G10*I10,2) -> 252.56 | N10: =ROUND((G10*I10)-K10-L10-M10,2) -> 252.56 | P10: =ROUND(IF(D10=0,IF((N10-E10-O10)>0,(N10-E10-O10),0),IF((D10+N10-O10)>0,(D10+N10-O10),0)),2) -> 1515.36 | Q10: =ROUND(IF(E10=0,IF((D10+N10-O10)<0,ABS(D10+N10-O10),0),IF((N10-E10-O10)<0,ABS(N10-E10-O10),0)),2) -> 0
A11: 5 | B11: =червень!B11 -> Семко Л.І. | C11: 1005 | D11: =червень!P11 -> 3341.01 | E11: =червень!Q11 -> 0 | F11: =червень!F11 -> 0 | G11: =червень!G11 -> 28.34 | H11: =червень!H11 -> 0 | I11: =червень!I11 -> 4.1 | J11: =ROUND(G11*I11,2) -> 116.19 | N11: =ROUND((G11*I11)-K11-L11-M11,2) -> 116.19 | P11: =ROUND(IF(D11=0,IF((N11-E11-O11)>0,(N11-E11-O11),0),IF((D11+N11-O11)>0,(D11+N11-O11),0)),2) -> 3457.2 | Q11: =ROUND(IF(E11=0,IF((D11+N11-O11)<0,ABS(D11+N11-O11),0),IF((N11-E11-O11)<0,ABS(N11-E11-O11),0)),2) -> 0
A12: 5 | B12: =червень!B12 -> Гаркуша Н.І. | C12: 1005-а | D12: =червень!P12 -> 1711.12 | E12: =червень!Q12 -> 0 | F12: =червень!F12 -> 0 | G12: =червень!G12 -> 36.66 | H12: =червень!H12 -> 0 | I12: =червень!I12 -> 4.1 | J12: =ROUND(G12*I12,2) -> 150.31 | N12: =ROUND((G12*I12)-K12-L12-M12,2) -> 150.31 | P12: =ROUND(IF(D12=0,IF((N12-E12-O12)>0,(N12-E12-O12),0),IF((D12+N12-O12)>0,(D12+N12-O12),0)),2) -> 1861.43 | Q12: =ROUND(IF(E12=0,IF((D12+N12-O12)<0,ABS(D12+N12-O12),0),IF((N12-E12-O12)<0,ABS(N12-E12-O12),0)),2) -> 0
A13: 6 | B13: =червень!B13 -> Андріяшев В.М | C13: 1006 | D13: =червень!P13 -> 1359.64 | E13: =червень!Q13 -> 0 | F13: =червень!F13 -> 0 | G13: =червень!G13 -> 49.8 | H13: =червень!H13 -> 0 | I13: =червень!I13 -> 4.1 | J13: =ROUND(G13*I13,2) -> 204.18 | N13: =ROUND((G13*I13)-K13-L13-M13,2) -> 204.18 | P13: =ROUND(IF(D13=0,IF((N13-E13-O13)>0,(N13-E13-O13),0),IF((D13+N13-O13)>0,(D13+N13-O13),0)),2) -> 1563.82 | Q13: =ROUND(IF(E13=0,IF((D13+N13-O13)<0,ABS(D13+N13-O13),0),IF((N13-E13-O13)<0,ABS(N13-E13-O13),0)),2) -> 0
A14: 7 | B14: =червень!B14 -> Старчикова О.М. | C14: 1007 | D14: =червень!P14 -> 994.49 | E14: =червень!Q14 -> 0 | F14: =червень!F14 -> 0 | G14: =червень!G14 -> 34.65 | H14: =червень!H14 -> 0 | I14: =червень!I14 -> 4.1 | J14: =ROUND(G14*I14,2) -> 142.07 | N14: =ROUND((G14*I14)-K14-L14-M14,2) -> 142.07 | P14: =ROUND(IF(D14=0,IF((N14-E14-O14)>0,(N14-E14-O14),0),IF((D14+N14-O14)>0,(D14+N14-O14),0)),2) -> 1136.56 | Q14: =ROUND(IF(E14=0,IF((D14+N14-O14)<0,ABS(D14+N14-O14),0),IF((N14-E14-O14)<0,ABS(N14-E14-O14),0)),2) -> 0
A15: 8 | B15: =червень!B15 -> Безер Т.М | C15: 1008 | D15: =червень!P15 -> 1521.59 | E15: =червень!Q15 -> 0 | F15: =червень!F15 -> 0 | G15: =червень!G15 -> 62.14 | H15: =червень!H15 -> 0 | I15: =червень!I15 -> 4.1 | J15: =ROUND(G15*I15,2) -> 254.77 | N15: =ROUND((G15*I15)-K15-L15-M15,2) -> 254.77 | P15: =ROUND(IF(D15=0,IF((N15-E15-O15)>0,(N15-E15-O15),0),IF((D15+N15-O15)>0,(D15+N15-O15),0)),2) -> 1776.36 | Q15: =ROUND(IF(E15=0,IF((D15+N15-O15)<0,ABS(D15+N15-O15),0),IF((N15-E15-O15)<0,ABS(N15-E15-O15),0)),2) -> 0
A16: 9 | B16: =червень!B16 -> Решетило М.М | C16: 1009 | D16: =червень!P16 -> 2404.68 | E16: =червень!Q16 -> 0 | F16: =червень!F16 -> 0 | G16: =червень!G16 -> 65.16 | H16: =червень!H16 -> 0 | I16: =червень!I16 -> 4.1 | J16: =ROUND(G16*I16,2) -> 267.16 | N16: =ROUND((G16*I16)-K16-L16-M16,2) -> 267.16 | P16: =ROUND(IF(D16=0,IF((N16-E16-O16)>0,(N16-E16-O16),0),IF((D16+N16-O16)>0,(D16+N16-O16),0)),2) -> 2671.84 | Q16: =ROUND(IF(E16=0,IF((D16+N16-O16)<0,ABS(D16+N16-O16),0),IF((N16-E16-O16)<0,ABS(N16-E16-O16),0)),2) -> 0
A17: 10 | B17: =червень!B17 -> Фесенко О.В. | C17: 1010 | D17: =червень!P17 -> 6109.15 | E17: =червень!Q17 -> 0 | F17: =червень!F17 -> 0 | G17: =червень!G17 -> 50.1 | H17: =червень!H17 -> 0 | I17: =червень!I17 -> 4.1 | J17: =ROUND(G17*I17,2) -> 205.41 | N17: =ROUND((G17*I17)-K17-L17-M17,2) -> 205.41 | P17: =ROUND(IF(D17=0,IF((N17-E17-O17)>0,(N17-E17-O17),0),IF((D17+N17-O17)>0,(D17+N17-O17),0)),2) -> 6314.56 | Q17: =ROUND(IF(E17=0,IF((D17+N17-O17)<0,ABS(D17+N17-O17),0),IF((N17-E17-O17)<0,ABS(N17-E17-O17),0)),2) -> 0
A18: 11 | B18: =червень!B18 -> Петренко О.М. | C18: 1011 | D18: =червень!P18 -> 2414.12 | E18: =червень!Q18 -> 0 | F18: =червень!F18 -> 0 | G18: =червень!G18 -> 35.2 | H18: =червень!H18 -> 0 | I18: =червень!I18 -> 4.1 | J18: =ROUND(G18*I18,2) -> 144.32 | N18: =ROUND((G18*I18)-K18-L18-M18,2) -> 144.32 | P18: =ROUND(IF(D18=0,IF((N18-E18-O18)>0,(N18-E18-O18),0),IF((D18+N18-O18)>0,(D18+N18-O18),0)),2) -> 2558.44 | Q18: =ROUND(IF(E18=0,IF((D18+N18-O18)<0,ABS(D18+N18-O18),0),IF((N18-E18-O18)<0,ABS(N18-E18-O18),0)),2) -> 0
... A221: 213 | B221: =червень!B221 -> Корнюшенко О.О. | C221: 60213 | D221: =червень!P221 -> 9050 | E221: =червень!Q221 -> 0 | F221: =червень!F221 -> 0 | G221: =червень!G221 -> 62 | H221: =червень!H221 -> 0 | I221: =червень!I221 -> 4.1 | J221: =ROUND(G221*I221,2) -> 254.2 | N221: =ROUND((G221*I221)-K221-L221-M221,2) -> 254.2 | P221: =ROUND(IF(D221=0,IF((N221-E221-O221)>0,(N221-E221-O221),0),IF((D221+N221-O221)>0,(D221+N221-O221),0)),2) -> 9304.2 | Q221: =ROUND(IF(E221=0,IF((D221+N221-O221)<0,ABS(D221+N221-O221),0),IF((N221-E221-O221)<0,ABS(N221-E221-O221),0)),2) -> 0
